Workbook

Sheet Trésorerie
D2: 44561 | E2: 2022 | Q2: 44926 | R2: 2023 | AD2: 2024
C3: Solde de Trésorerie (CC+CM+Caisse) : | D3: =207964.31+100711.45+1229.06 -> 309904.82 | E3: =D3+E43+E71 -> 200930.88 | F3: =E3+F43+F71 -> 249307.44 | G3: =F3+G43+G71 -> 297762.78 | H3: =G3+H43+H71 -> 227618.05 | I3: =H3+I43+I71 -> 271818 | J3: =I3+J43+J71 -> 296726.8 | K3: =J3+K43+K71 -> 220757.38 | L3: =K3+L43+L71 -> 104408.7 | M3: =L3+M43+M71+90000 -> 97952.77 | N3: =M3+N43+N71 -> 299366.99 | O3: =N3+O43+O71 -> 331662.62 | P3: =O3+P43+P71 -> 203888.9 | Q3: =109619.71+92951.16+1380.7 -> 203951.57 | R3: =Q3+R43+R71+40000 -> 79651.43 | S3: =R3+S43+S71+95006.53 -> 82184.66 | T3: =S3+T43+T71 -> 366194.25 | U3: =T3+U43+U71 -> 383255.87 | V3: =U3+V43+V71 -> 355386.51 | W3: =V3+W43+W71 -> 405582.13 | X3: =W3+X43+X71 -> 452749.75 | Y3: =X3+Y43+Y71 -> 320465.3 | Z3: =Y3+Z43+Z71 -> 518238.26 | AA3: =Z3+AA43+AA71 -> 522684.11 | ... AC3: =AB3+AC43+AC71 -> 259616.29 | AD3: =AC3+R72 -> 95316.15 | AE3: =AD3+S72 -> 2842.85 | AF3: =AE3+T72 -> 286852.44 | AG3: =AF3+U72 -> 303914.06
E4: 1 | F4: 2 | G4: 3 | H4: 4 | I4: 5 | J4: 6 | K4: 7 | L4: 8 | M4: 9 | N4: 10 | O4: 11 | P4: 12 | R4: 1 | S4: 2 | T4: 3 | U4: 4 | V4: 5 | W4: 6 | X4: 7 | Y4: 8 | Z4: 9 | AA4: 10 | AB4: 11 | AC4: 12 | AD4: 1 | AE4: 2 | AF4: 3 | AG4: 4
A5: =SUM(E5:P5) -> 553708.3 | B5: 468740 | C5: VILLE A RECEVOIR | D5: Entrée | E5: =-SUMIFS('2022'!$M:$M,'2022'!$E:$E,Trésorerie!E$4,'2022'!$F:$F,Trésorerie!$B5)+SUMIFS('2022'!$N:$N,'2022'!$E:$E,Trésorerie!E$4,'2022'!$F:$F,Trésorerie!$B5) -> 0 | F5: =-SUMIFS('2022'!$M:$M,'2022'!$E:$E,Trésorerie!F$4,'2022'!$F:$F,Trésorerie!$B5)+SUMIFS('2022'!$N:$N,'2022'!$E:$E,Trésorerie!F$4,'2022'!$F:$F,Trésorerie!$B5) -> 172245.3 | G5: =-SUMIFS('2022'!$M:$M,'2022'!$E:$E,Trésorerie!G$4,'2022'!$F:$F,Trésorerie!$B5)+SUMIFS('2022'!$N:$N,'2022'!$E:$E,Trésorerie!G$4,'2022'!$F:$F,Trésorerie!$B5) -> 123296 | H5: =-SUMIFS('2022'!$M:$M,'2022'!$E:$E,Trésorerie!H$4,'2022'!$F:$F,Trésorerie!$B5)+SUMIFS('2022'!$N:$N,'2022'!$E:$E,Trésorerie!H$4,'2022'!$F:$F,Trésorerie!$B5) -> 17000 | I5: =-SUMIFS('2022'!$M:$M,'2022'!$E:$E,Trésorerie!I$4,'2022'!$F:$F,Trésorerie!$B5)+SUMIFS('2022'!$N:$N,'2022'!$E:$E,Trésorerie!I$4,'2022'!$F:$F,Trésorerie!$B5) -> 0 | J5: =-SUMIFS('2022'!$M:$M,'2022'!$E:$E,Trésorerie!J$4,'2022'!$F:$F,Trésorerie!$B5)+SUMIFS('2022'!$N:$N,'2022'!$E:$E,Trésorerie!J$4,'2022'!$F:$F,Trésorerie!$B5) -> 11099.8 | K5: =-SUMIFS('2022'!$M:$M,'2022'!$E:$E,Trésorerie!K$4,'2022'!$F:$F,Trésorerie!$B5)+SUMIFS('2022'!$N:$N,'2022'!$E:$E,Trésorerie!K$4,'2022'!$F:$F,Trésorerie!$B5) -> 1200 | L5: =-SUMIFS('2022'!$M:$M,'2022'!$E:$E,Trésorerie!L$4,'2022'!$F:$F,Trésorerie!$B5)+SUMIFS('2022'!$N:$N,'2022'!$E:$E,Trésorerie!L$4,'2022'!$F:$F,Trésorerie!$B5) -> 169.2 | ... P5: =-SUMIFS('2022'!$M:$M,'2022'!$E:$E,Trésorerie!P$4,'2022'!$F:$F,Trésorerie!$B5)+SUMIFS('2022'!$N:$N,'2022'!$E:$E,Trésorerie!P$4,'2022'!$F:$F,Trésorerie!$B5) -> 344 | R5: =-SUMIFS('2023-01'!$M:$M,'2023-01'!$E:$E,Trésorerie!R$4,'2023-01'!$F:$F,Trésorerie!$B5)+SUMIFS('2023-01'!$N:$N,'2023-01'!$E:$E,Trésorerie!R$4,'2023-01'!$F:$F,Trésorerie!$B5) -> 430 | S5: =-SUMIFS('2023-02'!$M:$M,'2023-02'!$E:$E,Trésorerie!S$4,'2023-02'!$F:$F,Trésorerie!$B5)+SUMIFS('2023-02'!$N:$N,'2023-02'!$E:$E,Trésorerie!S$4,'2023-02'!$F:$F,Trésorerie!$B5) -> 0 | T5: =-SUMIFS('2023-03'!$M:$M,'2023-03'!$E:$E,Trésorerie!T$4,'2023-03'!$F:$F,Trésorerie!$B5)+SUMIFS('2023-03'!$N:$N,'2023-03'!$E:$E,Trésorerie!T$4,'2023-03'!$F:$F,Trésorerie!$B5) -> 176370 | U5: =-SUMIFS('2023-04'!$M:$M,'2023-04'!$E:$E,Trésorerie!U$4,'2023-04'!$F:$F,Trésorerie!$B5)+SUMIFS('2023-04'!$N:$N,'2023-04'!$E:$E,Trésorerie!U$4,'2023-04'!$F:$F,Trésorerie!$B5) -> 88447.5 | V5: =-SUMIFS('2023-05'!$M:$M,'2023-05'!$E:$E,Trésorerie!V$4,'2023-05'!$F:$F,Trésorerie!$B5)+SUMIFS('2023-05'!$N:$N,'2023-05'!$E:$E,Trésorerie!V$4,'2023-05'!$F:$F,Trésorerie!$B5) -> 473 | W5: =-SUMIFS('2023-06'!$M:$M,'2023-06'!$E:$E,Trésorerie!W$4,'2023-06'!$F:$F,Trésorerie!$B5)+SUMIFS('2023-06'!$N:$N,'2023-06'!$E:$E,Trésorerie!W$4,'2023-06'!$F:$F,Trésorerie!$B5) -> 0 | X5: =-SUMIFS('2023-07'!$M:$M,'2023-07'!$E:$E,Trésorerie!X$4,'2023-07'!$F:$F,Trésorerie!$B5)+SUMIFS('2023-07'!$N:$N,'2023-07'!$E:$E,Trésorerie!X$4,'2023-07'!$F:$F,Trésorerie!$B5) -> 54000 | Y5: =-SUMIFS('2023-08'!$M:$M,'2023-08'!$E:$E,Trésorerie!Y$4,'2023-08'!$F:$F,Trésorerie!$B5)+SUMIFS('2023-08'!$N:$N,'2023-08'!$E:$E,Trésorerie!Y$4,'2023-08'!$F:$F,Trésorerie!$B5) -> 6774 | Z5: =-SUMIFS('2023-09'!$M:$M,'2023-09'!$E:$E,Trésorerie!Z$4,'2023-09'!$F:$F,Trésorerie!$B5)+SUMIFS('2023-09'!$N:$N,'2023-09'!$E:$E,Trésorerie!Z$4,'2023-09'!$F:$F,Trésorerie!$B5) -> 161766.5 | AA5: =-SUMIFS('2023-10'!$M:$M,'2023-10'!$E:$E,Trésorerie!AA$4,'2023-10'!$F:$F,Trésorerie!$B5)+SUMIFS('2023-10'!$N:$N,'2023-10'!$E:$E,Trésorerie!AA$4,'2023-10'!$F:$F,Trésorerie!$B5) -> 5200 | AB5: =IF(SUM($E5:O5)>SUM($R5:AA5),SUM($E5:O5)-SUM($R5:AA5),0) -> 59903.3 | AC5: =IF(SUM($E5:P5)>SUM($R5:AB5),SUM($E5:P5)-SUM($R5:AB5),0) -> 344
A6: =SUM(E6:P6) -> 173624.12 | B6: 445020 | C6: CAF PS BABILHOME | D6: Entrée | E6: =-SUMIFS('2022'!$M:$M,'2022'!$E:$E,Trésorerie!E$4,'2022'!$F:$F,Trésorerie!$B6)+SUMIFS('2022'!$N:$N,'2022'!$E:$E,Trésorerie!E$4,'2022'!$F:$F,Trésorerie!$B6) -> 0 | F6: =-SUMIFS('2022'!$M:$M,'2022'!$E:$E,Trésorerie!F$4,'2022'!$F:$F,Trésorerie!$B6)+SUMIFS('2022'!$N:$N,'2022'!$E:$E,Trésorerie!F$4,'2022'!$F:$F,Trésorerie!$B6) -> 0 | G6: =-SUMIFS('2022'!$M:$M,'2022'!$E:$E,Trésorerie!G$4,'2022'!$F:$F,Trésorerie!$B6)+SUMIFS('2022'!$N:$N,'2022'!$E:$E,Trésorerie!G$4,'2022'!$F:$F,Trésorerie!$B6) -> 0 | H6: =-SUMIFS('2022'!$M:$M,'2022'!$E:$E,Trésorerie!H$4,'2022'!$F:$F,Trésorerie!$B6)+SUMIFS('2022'!$N:$N,'2022'!$E:$E,Trésorerie!H$4,'2022'!$F:$F,Trésorerie!$B6) -> 18666 | I6: =-SUMIFS('2022'!$M:$M,'2022'!$E:$E,Trésorerie!I$4,'2022'!$F:$F,Trésorerie!$B6)+SUMIFS('2022'!$N:$N,'2022'!$E:$E,Trésorerie!I$4,'2022'!$F:$F,Trésorerie!$B6) -> 52278.63 | J6: =-SUMIFS('2022'!$M:$M,'2022'!$E:$E,Trésorerie!J$4,'2022'!$F:$F,Trésorerie!$B6)+SUMIFS('2022'!$N:$N,'2022'!$E:$E,Trésorerie!J$4,'2022'!$F:$F,Trésorerie!$B6) -> 47050.76 | K6: =-SUMIFS('2022'!$M:$M,'2022'!$E:$E,Trésorerie!K$4,'2022'!$F:$F,Trésorerie!$B6)+SUMIFS('2022'!$N:$N,'2022'!$E:$E,Trésorerie!K$4,'2022'!$F:$F,Trésorerie!$B6) -> 23987.2 | L6: =-SUMIFS('2022'!$M:$M,'2022'!$E:$E,Trésorerie!L$4,'2022'!$F:$F,Trésorerie!$B6)+SUMIFS('2022'!$N:$N,'2022'!$E:$E,Trésorerie!L$4,'2022'!$F:$F,Trésorerie!$B6) -> 0 | ... P6: =-SUMIFS('2022'!$M:$M,'2022'!$E:$E,Trésorerie!P$4,'2022'!$F:$F,Trésorerie!$B6)+SUMIFS('2022'!$N:$N,'2022'!$E:$E,Trésorerie!P$4,'2022'!$F:$F,Trésorerie!$B6) -> 0 | R6: =-SUMIFS('2023-01'!$M:$M,'2023-01'!$E:$E,Trésorerie!R$4,'2023-01'!$F:$F,Trésorerie!$B6)+SUMIFS('2023-01'!$N:$N,'2023-01'!$E:$E,Trésorerie!R$4,'2023-01'!$F:$F,Trésorerie!$B6) -> 0 | S6: =-SUMIFS('2023-02'!$M:$M,'2023-02'!$E:$E,Trésorerie!S$4,'2023-02'!$F:$F,Trésorerie!$B6)+SUMIFS('2023-02'!$N:$N,'2023-02'!$E:$E,Trésorerie!S$4,'2023-02'!$F:$F,Trésorerie!$B6) -> 0 | T6: =-SUMIFS('2023-03'!$M:$M,'2023-03'!$E:$E,Trésorerie!T$4,'2023-03'!$F:$F,Trésorerie!$B6)+SUMIFS('2023-03'!$N:$N,'2023-03'!$E:$E,Trésorerie!T$4,'2023-03'!$F:$F,Trésorerie!$B6) -> 79819.26 | U6: =-SUMIFS('2023-04'!$M:$M,'2023-04'!$E:$E,Trésorerie!U$4,'2023-04'!$F:$F,Trésorerie!$B6)+SUMIFS('2023-04'!$N:$N,'2023-04'!$E:$E,Trésorerie!U$4,'2023-04'!$F:$F,Trésorerie!$B6) -> 0 | V6: =-SUMIFS('2023-05'!$M:$M,'2023-05'!$E:$E,Trésorerie!V$4,'2023-05'!$F:$F,Trésorerie!$B6)+SUMIFS('2023-05'!$N:$N,'2023-05'!$E:$E,Trésorerie!V$4,'2023-05'!$F:$F,Trésorerie!$B6) -> 0 | W6: =-SUMIFS('2023-06'!$M:$M,'2023-06'!$E:$E,Trésorerie!W$4,'2023-06'!$F:$F,Trésorerie!$B6)+SUMIFS('2023-06'!$N:$N,'2023-06'!$E:$E,Trésorerie!W$4,'2023-06'!$F:$F,Trésorerie!$B6) -> 47728.19 | X6: =-SUMIFS('2023-07'!$M:$M,'2023-07'!$E:$E,Trésorerie!X$4,'2023-07'!$F:$F,Trésorerie!$B6)+SUMIFS('2023-07'!$N:$N,'2023-07'!$E:$E,Trésorerie!X$4,'2023-07'!$F:$F,Trésorerie!$B6) -> 0 | Y6: =-SUMIFS('2023-08'!$M:$M,'2023-08'!$E:$E,Trésorerie!Y$4,'2023-08'!$F:$F,Trésorerie!$B6)+SUMIFS('2023-08'!$N:$N,'2023-08'!$E:$E,Trésorerie!Y$4,'2023-08'!$F:$F,Trésorerie!$B6) -> 0 | Z6: =-SUMIFS('2023-09'!$M:$M,'2023-09'!$E:$E,Trésorerie!Z$4,'2023-09'!$F:$F,Trésorerie!$B6)+SUMIFS('2023-09'!$N:$N,'2023-09'!$E:$E,Trésorerie!Z$4,'2023-09'!$F:$F,Trésorerie!$B6) -> 45258.77 | AA6: =-SUMIFS('2023-10'!$M:$M,'2023-10'!$E:$E,Trésorerie!AA$4,'2023-10'!$F:$F,Trésorerie!$B6)+SUMIFS('2023-10'!$N:$N,'2023-10'!$E:$E,Trésorerie!AA$4,'2023-10'!$F:$F,Trésorerie!$B6) -> 0 | AB6: =IF(SUM($E6:O6)>SUM($R6:AA6),SUM($E6:O6)-SUM($R6:AA6),0) -> 817.9 | AC6: =IF(SUM($E6:P6)>SUM($R6:AB6),SUM($E6:P6)-SUM($R6:AB6),0) -> 0
A7: =SUM(E7:P7) -> 162124.29 | B7: 445030 | C7: CAF PS GRIBOUILLE | D7: Entrée | E7: =-SUMIFS('2022'!$M:$M,'2022'!$E:$E,Trésorerie!E$4,'2022'!$F:$F,Trésorerie!$B7)+SUMIFS('2022'!$N:$N,'2022'!$E:$E,Trésorerie!E$4,'2022'!$F:$F,Trésorerie!$B7) -> 0 | F7: =-SUMIFS('2022'!$M:$M,'2022'!$E:$E,Trésorerie!F$4,'2022'!$F:$F,Trésorerie!$B7)+SUMIFS('2022'!$N:$N,'2022'!$E:$E,Trésorerie!F$4,'2022'!$F:$F,Trésorerie!$B7) -> 0 | G7: =-SUMIFS('2022'!$M:$M,'2022'!$E:$E,Trésorerie!G$4,'2022'!$F:$F,Trésorerie!$B7)+SUMIFS('2022'!$N:$N,'2022'!$E:$E,Trésorerie!G$4,'2022'!$F:$F,Trésorerie!$B7) -> 0 | H7: =-SUMIFS('2022'!$M:$M,'2022'!$E:$E,Trésorerie!H$4,'2022'!$F:$F,Trésorerie!$B7)+SUMIFS('2022'!$N:$N,'2022'!$E:$E,Trésorerie!H$4,'2022'!$F:$F,Trésorerie!$B7) -> 0 | I7: =-SUMIFS('2022'!$M:$M,'2022'!$E:$E,Trésorerie!I$4,'2022'!$F:$F,Trésorerie!$B7)+SUMIFS('2022'!$N:$N,'2022'!$E:$E,Trésorerie!I$4,'2022'!$F:$F,Trésorerie!$B7) -> 35683.97 | J7: =-SUMIFS('2022'!$M:$M,'2022'!$E:$E,Trésorerie!J$4,'2022'!$F:$F,Trésorerie!$B7)+SUMIFS('2022'!$N:$N,'2022'!$E:$E,Trésorerie!J$4,'2022'!$F:$F,Trésorerie!$B7) -> 37199.36 | K7: =-SUMIFS('2022'!$M:$M,'2022'!$E:$E,Trésorerie!K$4,'2022'!$F:$F,Trésorerie!$B7)+SUMIFS('2022'!$N:$N,'2022'!$E:$E,Trésorerie!K$4,'2022'!$F:$F,Trésorerie!$B7) -> 53774.63 | L7: =-SUMIFS('2022'!$M:$M,'2022'!$E:$E,Trésorerie!L$4,'2022'!$F:$F,Trésorerie!$B7)+SUMIFS('2022'!$N:$N,'2022'!$E:$E,Trésorerie!L$4,'2022'!$F:$F,Trésorerie!$B7) -> 0 | ... P7: =-SUMIFS('2022'!$M:$M,'2022'!$E:$E,Trésorerie!P$4,'2022'!$F:$F,Trésorerie!$B7)+SUMIFS('2022'!$N:$N,'2022'!$E:$E,Trésorerie!P$4,'2022'!$F:$F,Trésorerie!$B7) -> 0 | R7: =-SUMIFS('2023-01'!$M:$M,'2023-01'!$E:$E,Trésorerie!R$4,'2023-01'!$F:$F,Trésorerie!$B7)+SUMIFS('2023-01'!$N:$N,'2023-01'!$E:$E,Trésorerie!R$4,'2023-01'!$F:$F,Trésorerie!$B7) -> 0 | S7: =-SUMIFS('2023-02'!$M:$M,'2023-02'!$E:$E,Trésorerie!S$4,'2023-02'!$F:$F,Trésorerie!$B7)+SUMIFS('2023-02'!$N:$N,'2023-02'!$E:$E,Trésorerie!S$4,'2023-02'!$F:$F,Trésorerie!$B7) -> 0 | T7: =-SUMIFS('2023-03'!$M:$M,'2023-03'!$E:$E,Trésorerie!T$4,'2023-03'!$F:$F,Trésorerie!$B7)+SUMIFS('2023-03'!$N:$N,'2023-03'!$E:$E,Trésorerie!T$4,'2023-03'!$F:$F,Trésorerie!$B7) -> 66666.06 | U7: =-SUMIFS('2023-04'!$M:$M,'2023-04'!$E:$E,Trésorerie!U$4,'2023-04'!$F:$F,Trésorerie!$B7)+SUMIFS('2023-04'!$N:$N,'2023-04'!$E:$E,Trésorerie!U$4,'2023-04'!$F:$F,Trésorerie!$B7) -> 0 | V7: =-SUMIFS('2023-05'!$M:$M,'2023-05'!$E:$E,Trésorerie!V$4,'2023-05'!$F:$F,Trésorerie!$B7)+SUMIFS('2023-05'!$N:$N,'2023-05'!$E:$E,Trésorerie!V$4,'2023-05'!$F:$F,Trésorerie!$B7) -> 0 | W7: =-SUMIFS('2023-06'!$M:$M,'2023-06'!$E:$E,Trésorerie!W$4,'2023-06'!$F:$F,Trésorerie!$B7)+SUMIFS('2023-06'!$N:$N,'2023-06'!$E:$E,Trésorerie!W$4,'2023-06'!$F:$F,Trésorerie!$B7) -> 0 | X7: =-SUMIFS('2023-07'!$M:$M,'2023-07'!$E:$E,Trésorerie!X$4,'2023-07'!$F:$F,Trésorerie!$B7)+SUMIFS('2023-07'!$N:$N,'2023-07'!$E:$E,Trésorerie!X$4,'2023-07'!$F:$F,Trésorerie!$B7) -> 0 | Y7: =-SUMIFS('2023-08'!$M:$M,'2023-08'!$E:$E,Trésorerie!Y$4,'2023-08'!$F:$F,Trésorerie!$B7)+SUMIFS('2023-08'!$N:$N,'2023-08'!$E:$E,Trésorerie!Y$4,'2023-08'!$F:$F,Trésorerie!$B7) -> 0 | Z7: =-SUMIFS('2023-09'!$M:$M,'2023-09'!$E:$E,Trésorerie!Z$4,'2023-09'!$F:$F,Trésorerie!$B7)+SUMIFS('2023-09'!$N:$N,'2023-09'!$E:$E,Trésorerie!Z$4,'2023-09'!$F:$F,Trésorerie!$B7) -> 31089.94 | AA7: =-SUMIFS('2023-10'!$M:$M,'2023-10'!$E:$E,Trésorerie!AA$4,'2023-10'!$F:$F,Trésorerie!$B7)+SUMIFS('2023-10'!$N:$N,'2023-10'!$E:$E,Trésorerie!AA$4,'2023-10'!$F:$F,Trésorerie!$B7) -> 0 | AB7: =IF(SUM($E7:O7)>SUM($R7:AA7),SUM($E7:O7)-SUM($R7:AA7),0) -> 64368.29 | AC7: =IF(SUM($E7:P7)>SUM($R7:AB7),SUM($E7:P7)-SUM($R7:AB7),0) -> 0
A8: =SUM(E8:P8) -> 141360.8 | B8: 445050 | C8: CAF PS PILOTAGE ANIMATION GLOBALE | D8: Entrée | E8: =-SUMIFS('2022'!$M:$M,'2022'!$E:$E,Trésorerie!E$4,'2022'!$F:$F,Trésorerie!$B8)+SUMIFS('2022'!$N:$N,'2022'!$E:$E,Trésorerie!E$4,'2022'!$F:$F,Trésorerie!$B8) -> 0 | F8: =-SUMIFS('2022'!$M:$M,'2022'!$E:$E,Trésorerie!F$4,'2022'!$F:$F,Trésorerie!$B8)+SUMIFS('2022'!$N:$N,'2022'!$E:$E,Trésorerie!F$4,'2022'!$F:$F,Trésorerie!$B8) -> 0 | G8: =-SUMIFS('2022'!$M:$M,'2022'!$E:$E,Trésorerie!G$4,'2022'!$F:$F,Trésorerie!$B8)+SUMIFS('2022'!$N:$N,'2022'!$E:$E,Trésorerie!G$4,'2022'!$F:$F,Trésorerie!$B8) -> 31853.22 | H8: =-SUMIFS('2022'!$M:$M,'2022'!$E:$E,Trésorerie!H$4,'2022'!$F:$F,Trésorerie!$B8)+SUMIFS('2022'!$N:$N,'2022'!$E:$E,Trésorerie!H$4,'2022'!$F:$F,Trésorerie!$B8) -> 0 | I8: =-SUMIFS('2022'!$M:$M,'2022'!$E:$E,Trésorerie!I$4,'2022'!$F:$F,Trésorerie!$B8)+SUMIFS('2022'!$N:$N,'2022'!$E:$E,Trésorerie!I$4,'2022'!$F:$F,Trésorerie!$B8) -> 45801.06 | J8: =-SUMIFS('2022'!$M:$M,'2022'!$E:$E,Trésorerie!J$4,'2022'!$F:$F,Trésorerie!$B8)+SUMIFS('2022'!$N:$N,'2022'!$E:$E,Trésorerie!J$4,'2022'!$F:$F,Trésorerie!$B8) -> 0 | K8: =-SUMIFS('2022'!$M:$M,'2022'!$E:$E,Trésorerie!K$4,'2022'!$F:$F,Trésorerie!$B8)+SUMIFS('2022'!$N:$N,'2022'!$E:$E,Trésorerie!K$4,'2022'!$F:$F,Trésorerie!$B8) -> 0 | L8: =-SUMIFS('2022'!$M:$M,'2022'!$E:$E,Trésorerie!L$4,'2022'!$F:$F,Trésorerie!$B8)+SUMIFS('2022'!$N:$N,'2022'!$E:$E,Trésorerie!L$4,'2022'!$F:$F,Trésorerie!$B8) -> 0 | ... P8: =-SUMIFS('2022'!$M:$M,'2022'!$E:$E,Trésorerie!P$4,'2022'!$F:$F,Trésorerie!$B8)+SUMIFS('2022'!$N:$N,'2022'!$E:$E,Trésorerie!P$4,'2022'!$F:$F,Trésorerie!$B8) -> 0 | R8: =-SUMIFS('2023-01'!$M:$M,'2023-01'!$E:$E,Trésorerie!R$4,'2023-01'!$F:$F,Trésorerie!$B8)+SUMIFS('2023-01'!$N:$N,'2023-01'!$E:$E,Trésorerie!R$4,'2023-01'!$F:$F,Trésorerie!$B8) -> 0 | S8: =-SUMIFS('2023-02'!$M:$M,'2023-02'!$E:$E,Trésorerie!S$4,'2023-02'!$F:$F,Trésorerie!$B8)+SUMIFS('2023-02'!$N:$N,'2023-02'!$E:$E,Trésorerie!S$4,'2023-02'!$F:$F,Trésorerie!$B8) -> 0 | T8: =-SUMIFS('2023-03'!$M:$M,'2023-03'!$E:$E,Trésorerie!T$4,'2023-03'!$F:$F,Trésorerie!$B8)+SUMIFS('2023-03'!$N:$N,'2023-03'!$E:$E,Trésorerie!T$4,'2023-03'!$F:$F,Trésorerie!$B8) -> 31853.22 | U8: =-SUMIFS('2023-04'!$M:$M,'2023-04'!$E:$E,Trésorerie!U$4,'2023-04'!$F:$F,Trésorerie!$B8)+SUMIFS('2023-04'!$N:$N,'2023-04'!$E:$E,Trésorerie!U$4,'2023-04'!$F:$F,Trésorerie!$B8) -> 31853.26 | V8: =-SUMIFS('2023-05'!$M:$M,'2023-05'!$E:$E,Trésorerie!V$4,'2023-05'!$F:$F,Trésorerie!$B8)+SUMIFS('2023-05'!$N:$N,'2023-05'!$E:$E,Trésorerie!V$4,'2023-05'!$F:$F,Trésorerie!$B8) -> 0 | W8: =-SUMIFS('2023-06'!$M:$M,'2023-06'!$E:$E,Trésorerie!W$4,'2023-06'!$F:$F,Trésorerie!$B8)+SUMIFS('2023-06'!$N:$N,'2023-06'!$E:$E,Trésorerie!W$4,'2023-06'!$F:$F,Trésorerie!$B8) -> 13380.12 | X8: =-SUMIFS('2023-07'!$M:$M,'2023-07'!$E:$E,Trésorerie!X$4,'2023-07'!$F:$F,Trésorerie!$B8)+SUMIFS('2023-07'!$N:$N,'2023-07'!$E:$E,Trésorerie!X$4,'2023-07'!$F:$F,Trésorerie!$B8) -> 31853.26 | Y8: =-SUMIFS('2023-08'!$M:$M,'2023-08'!$E:$E,Trésorerie!Y$4,'2023-08'!$F:$F,Trésorerie!$B8)+SUMIFS('2023-08'!$N:$N,'2023-08'!$E:$E,Trésorerie!Y$4,'2023-08'!$F:$F,Trésorerie!$B8) -> 0 | Z8: =-SUMIFS('2023-09'!$M:$M,'2023-09'!$E:$E,Trésorerie!Z$4,'2023-09'!$F:$F,Trésorerie!$B8)+SUMIFS('2023-09'!$N:$N,'2023-09'!$E:$E,Trésorerie!Z$4,'2023-09'!$F:$F,Trésorerie!$B8) -> 0 | AA8: =-SUMIFS('2023-10'!$M:$M,'2023-10'!$E:$E,Trésorerie!AA$4,'2023-10'!$F:$F,Trésorerie!$B8)+SUMIFS('2023-10'!$N:$N,'2023-10'!$E:$E,Trésorerie!AA$4,'2023-10'!$F:$F,Trésorerie!$B8) -> 31853.26 | AB8: =IF(SUM($E8:O8)>SUM($R8:AA8),SUM($E8:O8)-SUM($R8:AA8),0) -> 567.68 | AC8: =IF(SUM($E8:P8)>SUM($R8:AB8),SUM($E8:P8)-SUM($R8:AB8),0) -> 0
A9: =SUM(E9:P9) -> 108029.15 | B9: 511000 | C9: CH DIFFERES | D9: Entrée | E9: =-SUMIFS('2022'!$M:$M,'2022'!$E:$E,Trésorerie!E$4,'2022'!$F:$F,Trésorerie!$B9)+SUMIFS('2022'!$N:$N,'2022'!$E:$E,Trésorerie!E$4,'2022'!$F:$F,Trésorerie!$B9) -> 7551.88 | F9: =-SUMIFS('2022'!$M:$M,'2022'!$E:$E,Trésorerie!F$4,'2022'!$F:$F,Trésorerie!$B9)+SUMIFS('2022'!$N:$N,'2022'!$E:$E,Trésorerie!F$4,'2022'!$F:$F,Trésorerie!$B9) -> 13099.93 | G9: =-SUMIFS('2022'!$M:$M,'2022'!$E:$E,Trésorerie!G$4,'2022'!$F:$F,Trésorerie!$B9)+SUMIFS('2022'!$N:$N,'2022'!$E:$E,Trésorerie!G$4,'2022'!$F:$F,Trésorerie!$B9) -> 8928.19 | H9: =-SUMIFS('2022'!$M:$M,'2022'!$E:$E,Trésorerie!H$4,'2022'!$F:$F,Trésorerie!$B9)+SUMIFS('2022'!$N:$N,'2022'!$E:$E,Trésorerie!H$4,'2022'!$F:$F,Trésorerie!$B9) -> 7922.26 | I9: =-SUMIFS('2022'!$M:$M,'2022'!$E:$E,Trésorerie!I$4,'2022'!$F:$F,Trésorerie!$B9)+SUMIFS('2022'!$N:$N,'2022'!$E:$E,Trésorerie!I$4,'2022'!$F:$F,Trésorerie!$B9) -> 4306.24 | J9: =-SUMIFS('2022'!$M:$M,'2022'!$E:$E,Trésorerie!J$4,'2022'!$F:$F,Trésorerie!$B9)+SUMIFS('2022'!$N:$N,'2022'!$E:$E,Trésorerie!J$4,'2022'!$F:$F,Trésorerie!$B9) -> 13962.97 | K9: =-SUMIFS('2022'!$M:$M,'2022'!$E:$E,Trésorerie!K$4,'2022'!$F:$F,Trésorerie!$B9)+SUMIFS('2022'!$N:$N,'2022'!$E:$E,Trésorerie!K$4,'2022'!$F:$F,Trésorerie!$B9) -> 0 | L9: =-SUMIFS('2022'!$M:$M,'2022'!$E:$E,Trésorerie!L$4,'2022'!$F:$F,Trésorerie!$B9)+SUMIFS('2022'!$N:$N,'2022'!$E:$E,Trésorerie!L$4,'2022'!$F:$F,Trésorerie!$B9) -> 7478.7 | ... P9: =-SUMIFS('2022'!$M:$M,'2022'!$E:$E,Trésorerie!P$4,'2022'!$F:$F,Trésorerie!$B9)+SUMIFS('2022'!$N:$N,'2022'!$E:$E,Trésorerie!P$4,'2022'!$F:$F,Trésorerie!$B9) -> 7695.54 | R9: =-SUMIFS('2023-01'!$M:$M,'2023-01'!$E:$E,Trésorerie!R$4,'2023-01'!$F:$F,Trésorerie!$B9)+SUMIFS('2023-01'!$N:$N,'2023-01'!$E:$E,Trésorerie!R$4,'2023-01'!$F:$F,Trésorerie!$B9) -> 10472.39 | S9: =-SUMIFS('2023-02'!$M:$M,'2023-02'!$E:$E,Trésorerie!S$4,'2023-02'!$F:$F,Trésorerie!$B9)+SUMIFS('2023-02'!$N:$N,'2023-02'!$E:$E,Trésorerie!S$4,'2023-02'!$F:$F,Trésorerie!$B9) -> 16536.94 | T9: =-SUMIFS('2023-03'!$M:$M,'2023-03'!$E:$E,Trésorerie!T$4,'2023-03'!$F:$F,Trésorerie!$B9)+SUMIFS('2023-03'!$N:$N,'2023-03'!$E:$E,Trésorerie!T$4,'2023-03'!$F:$F,Trésorerie!$B9) -> 7603.93 | U9: =-SUMIFS('2023-04'!$M:$M,'2023-04'!$E:$E,Trésorerie!U$4,'2023-04'!$F:$F,Trésorerie!$B9)+SUMIFS('2023-04'!$N:$N,'2023-04'!$E:$E,Trésorerie!U$4,'2023-04'!$F:$F,Trésorerie!$B9) -> 10499.49 | V9: =-SUMIFS('2023-05'!$M:$M,'2023-05'!$E:$E,Trésorerie!V$4,'2023-05'!$F:$F,Trésorerie!$B9)+SUMIFS('2023-05'!$N:$N,'2023-05'!$E:$E,Trésorerie!V$4,'2023-05'!$F:$F,Trésorerie!$B9) -> 4135.27 | W9: =-SUMIFS('2023-06'!$M:$M,'2023-06'!$E:$E,Trésorerie!W$4,'2023-06'!$F:$F,Trésorerie!$B9)+SUMIFS('2023-06'!$N:$N,'2023-06'!$E:$E,Trésorerie!W$4,'2023-06'!$F:$F,Trésorerie!$B9) -> 0 | X9: =-SUMIFS('2023-07'!$M:$M,'2023-07'!$E:$E,Trésorerie!X$4,'2023-07'!$F:$F,Trésorerie!$B9)+SUMIFS('2023-07'!$N:$N,'2023-07'!$E:$E,Trésorerie!X$4,'2023-07'!$F:$F,Trésorerie!$B9) -> 26937.39 | Y9: =-SUMIFS('2023-08'!$M:$M,'2023-08'!$E:$E,Trésorerie!Y$4,'2023-08'!$F:$F,Trésorerie!$B9)+SUMIFS('2023-08'!$N:$N,'2023-08'!$E:$E,Trésorerie!Y$4,'2023-08'!$F:$F,Trésorerie!$B9) -> 0 | Z9: =-SUMIFS('2023-09'!$M:$M,'2023-09'!$E:$E,Trésorerie!Z$4,'2023-09'!$F:$F,Trésorerie!$B9)+SUMIFS('2023-09'!$N:$N,'2023-09'!$E:$E,Trésorerie!Z$4,'2023-09'!$F:$F,Trésorerie!$B9) -> 11311.02 | AA9: =-SUMIFS('2023-10'!$M:$M,'2023-10'!$E:$E,Trésorerie!AA$4,'2023-10'!$F:$F,Trésorerie!$B9)+SUMIFS('2023-10'!$N:$N,'2023-10'!$E:$E,Trésorerie!AA$4,'2023-10'!$F:$F,Trésorerie!$B9) -> 8009.76 | AB9: =IF(SUM($E9:O9)>SUM($R9:AA9),SUM($E9:O9)-SUM($R9:AA9),0) -> 4827.42 | AC9: =IF(SUM($E9:P9)>SUM($R9:AB9),SUM($E9:P9)-SUM($R9:AB9),0) -> 7695.54
A10: =SUM(E10:P10) -> 90202 | B10: 445060 | C10: CAF SUBV.FONCTIONNEMENT | D10: Entrée | E10: =-SUMIFS('2022'!$M:$M,'2022'!$E:$E,Trésorerie!E$4,'2022'!$F:$F,Trésorerie!$B10)+SUMIFS('2022'!$N:$N,'2022'!$E:$E,Trésorerie!E$4,'2022'!$F:$F,Trésorerie!$B10) -> 0 | F10: =-SUMIFS('2022'!$M:$M,'2022'!$E:$E,Trésorerie!F$4,'2022'!$F:$F,Trésorerie!$B10)+SUMIFS('2022'!$N:$N,'2022'!$E:$E,Trésorerie!F$4,'2022'!$F:$F,Trésorerie!$B10) -> 0 | G10: =-SUMIFS('2022'!$M:$M,'2022'!$E:$E,Trésorerie!G$4,'2022'!$F:$F,Trésorerie!$B10)+SUMIFS('2022'!$N:$N,'2022'!$E:$E,Trésorerie!G$4,'2022'!$F:$F,Trésorerie!$B10) -> 0 | H10: =-SUMIFS('2022'!$M:$M,'2022'!$E:$E,Trésorerie!H$4,'2022'!$F:$F,Trésorerie!$B10)+SUMIFS('2022'!$N:$N,'2022'!$E:$E,Trésorerie!H$4,'2022'!$F:$F,Trésorerie!$B10) -> 0 | I10: =-SUMIFS('2022'!$M:$M,'2022'!$E:$E,Trésorerie!I$4,'2022'!$F:$F,Trésorerie!$B10)+SUMIFS('2022'!$N:$N,'2022'!$E:$E,Trésorerie!I$4,'2022'!$F:$F,Trésorerie!$B10) -> 0 | J10: =-SUMIFS('2022'!$M:$M,'2022'!$E:$E,Trésorerie!J$4,'2022'!$F:$F,Trésorerie!$B10)+SUMIFS('2022'!$N:$N,'2022'!$E:$E,Trésorerie!J$4,'2022'!$F:$F,Trésorerie!$B10) -> 45101 | K10: =-SUMIFS('2022'!$M:$M,'2022'!$E:$E,Trésorerie!K$4,'2022'!$F:$F,Trésorerie!$B10)+SUMIFS('2022'!$N:$N,'2022'!$E:$E,Trésorerie!K$4,'2022'!$F:$F,Trésorerie!$B10) -> 0 | L10: =-SUMIFS('2022'!$M:$M,'2022'!$E:$E,Trésorerie!L$4,'2022'!$F:$F,Trésorerie!$B10)+SUMIFS('2022'!$N:$N,'2022'!$E:$E,Trésorerie!L$4,'2022'!$F:$F,Trésorerie!$B10) -> 0 | ... P10: =-SUMIFS('2022'!$M:$M,'2022'!$E:$E,Trésorerie!P$4,'2022'!$F:$F,Trésorerie!$B10)+SUMIFS('2022'!$N:$N,'2022'!$E:$E,Trésorerie!P$4,'2022'!$F:$F,Trésorerie!$B10) -> 0 | R10: =-SUMIFS('2023-01'!$M:$M,'2023-01'!$E:$E,Trésorerie!R$4,'2023-01'!$F:$F,Trésorerie!$B10)+SUMIFS('2023-01'!$N:$N,'2023-01'!$E:$E,Trésorerie!R$4,'2023-01'!$F:$F,Trésorerie!$B10) -> 0 | S10: =-SUMIFS('2023-02'!$M:$M,'2023-02'!$E:$E,Trésorerie!S$4,'2023-02'!$F:$F,Trésorerie!$B10)+SUMIFS('2023-02'!$N:$N,'2023-02'!$E:$E,Trésorerie!S$4,'2023-02'!$F:$F,Trésorerie!$B10) -> 0 | T10: =-SUMIFS('2023-03'!$M:$M,'2023-03'!$E:$E,Trésorerie!T$4,'2023-03'!$F:$F,Trésorerie!$B10)+SUMIFS('2023-03'!$N:$N,'2023-03'!$E:$E,Trésorerie!T$4,'2023-03'!$F:$F,Trésorerie!$B10) -> 0 | U10: =-SUMIFS('2023-04'!$M:$M,'2023-04'!$E:$E,Trésorerie!U$4,'2023-04'!$F:$F,Trésorerie!$B10)+SUMIFS('2023-04'!$N:$N,'2023-04'!$E:$E,Trésorerie!U$4,'2023-04'!$F:$F,Trésorerie!$B10) -> 0 | V10: =-SUMIFS('2023-05'!$M:$M,'2023-05'!$E:$E,Trésorerie!V$4,'2023-05'!$F:$F,Trésorerie!$B10)+SUMIFS('2023-05'!$N:$N,'2023-05'!$E:$E,Trésorerie!V$4,'2023-05'!$F:$F,Trésorerie!$B10) -> 0 | W10: =-SUMIFS('2023-06'!$M:$M,'2023-06'!$E:$E,Trésorerie!W$4,'2023-06'!$F:$F,Trésorerie!$B10)+SUMIFS('2023-06'!$N:$N,'2023-06'!$E:$E,Trésorerie!W$4,'2023-06'!$F:$F,Trésorerie!$B10) -> 44039 | X10: =-SUMIFS('2023-07'!$M:$M,'2023-07'!$E:$E,Trésorerie!X$4,'2023-07'!$F:$F,Trésorerie!$B10)+SUMIFS('2023-07'!$N:$N,'2023-07'!$E:$E,Trésorerie!X$4,'2023-07'!$F:$F,Trésorerie!$B10) -> 0 | Y10: =-SUMIFS('2023-08'!$M:$M,'2023-08'!$E:$E,Trésorerie!Y$4,'2023-08'!$F:$F,Trésorerie!$B10)+SUMIFS('2023-08'!$N:$N,'2023-08'!$E:$E,Trésorerie!Y$4,'2023-08'!$F:$F,Trésorerie!$B10) -> 0 | Z10: =-SUMIFS('2023-09'!$M:$M,'2023-09'!$E:$E,Trésorerie!Z$4,'2023-09'!$F:$F,Trésorerie!$B10)+SUMIFS('2023-09'!$N:$N,'2023-09'!$E:$E,Trésorerie!Z$4,'2023-09'!$F:$F,Trésorerie!$B10) -> 44039 | AA10: =-SUMIFS('2023-10'!$M:$M,'2023-10'!$E:$E,Trésorerie!AA$4,'2023-10'!$F:$F,Trésorerie!$B10)+SUMIFS('2023-10'!$N:$N,'2023-10'!$E:$E,Trésorerie!AA$4,'2023-10'!$F:$F,Trésorerie!$B10) -> 0 | AB10: =IF(SUM($E10:O10)>SUM($R10:AA10),SUM($E10:O10)-SUM($R10:AA10),0) -> 2124 | AC10: =IF(SUM($E10:P10)>SUM($R10:AB10),SUM($E10:P10)-SUM($R10:AB10),0) -> 0
A11: =SUM(E11:P11) -> 56340 | B11: 468710 | C11: METROPOLE GRD LYON A RECEVOIR | D11: Entrée | E11: =-SUMIFS('2022'!$M:$M,'2022'!$E:$E,Trésorerie!E$4,'2022'!$F:$F,Trésorerie!$B11)+SUMIFS('2022'!$N:$N,'2022'!$E:$E,Trésorerie!E$4,'2022'!$F:$F,Trésorerie!$B11) -> 0 | F11: =-SUMIFS('2022'!$M:$M,'2022'!$E:$E,Trésorerie!F$4,'2022'!$F:$F,Trésorerie!$B11)+SUMIFS('2022'!$N:$N,'2022'!$E:$E,Trésorerie!F$4,'2022'!$F:$F,Trésorerie!$B11) -> 0 | G11: =-SUMIFS('2022'!$M:$M,'2022'!$E:$E,Trésorerie!G$4,'2022'!$F:$F,Trésorerie!$B11)+SUMIFS('2022'!$N:$N,'2022'!$E:$E,Trésorerie!G$4,'2022'!$F:$F,Trésorerie!$B11) -> 9780 | H11: =-SUMIFS('2022'!$M:$M,'2022'!$E:$E,Trésorerie!H$4,'2022'!$F:$F,Trésorerie!$B11)+SUMIFS('2022'!$N:$N,'2022'!$E:$E,Trésorerie!H$4,'2022'!$F:$F,Trésorerie!$B11) -> 0 | I11: =-SUMIFS('2022'!$M:$M,'2022'!$E:$E,Trésorerie!I$4,'2022'!$F:$F,Trésorerie!$B11)+SUMIFS('2022'!$N:$N,'2022'!$E:$E,Trésorerie!I$4,'2022'!$F:$F,Trésorerie!$B11) -> 22820 | J11: =-SUMIFS('2022'!$M:$M,'2022'!$E:$E,Trésorerie!J$4,'2022'!$F:$F,Trésorerie!$B11)+SUMIFS('2022'!$N:$N,'2022'!$E:$E,Trésorerie!J$4,'2022'!$F:$F,Trésorerie!$B11) -> 0 | K11: =-SUMIFS('2022'!$M:$M,'2022'!$E:$E,Trésorerie!K$4,'2022'!$F:$F,Trésorerie!$B11)+SUMIFS('2022'!$N:$N,'2022'!$E:$E,Trésorerie!K$4,'2022'!$F:$F,Trésorerie!$B11) -> 0 | L11: =-SUMIFS('2022'!$M:$M,'2022'!$E:$E,Trésorerie!L$4,'2022'!$F:$F,Trésorerie!$B11)+SUMIFS('2022'!$N:$N,'2022'!$E:$E,Trésorerie!L$4,'2022'!$F:$F,Trésorerie!$B11) -> 0 | ... P11: =-SUMIFS('2022'!$M:$M,'2022'!$E:$E,Trésorerie!P$4,'2022'!$F:$F,Trésorerie!$B11)+SUMIFS('2022'!$N:$N,'2022'!$E:$E,Trésorerie!P$4,'2022'!$F:$F,Trésorerie!$B11) -> 0 | R11: =-SUMIFS('2023-01'!$M:$M,'2023-01'!$E:$E,Trésorerie!R$4,'2023-01'!$F:$F,Trésorerie!$B11)+SUMIFS('2023-01'!$N:$N,'2023-01'!$E:$E,Trésorerie!R$4,'2023-01'!$F:$F,Trésorerie!$B11) -> 0 | S11: =-SUMIFS('2023-02'!$M:$M,'2023-02'!$E:$E,Trésorerie!S$4,'2023-02'!$F:$F,Trésorerie!$B11)+SUMIFS('2023-02'!$N:$N,'2023-02'!$E:$E,Trésorerie!S$4,'2023-02'!$F:$F,Trésorerie!$B11) -> 0 | T11: =-SUMIFS('2023-03'!$M:$M,'2023-03'!$E:$E,Trésorerie!T$4,'2023-03'!$F:$F,Trésorerie!$B11)+SUMIFS('2023-03'!$N:$N,'2023-03'!$E:$E,Trésorerie!T$4,'2023-03'!$F:$F,Trésorerie!$B11) -> 0 | U11: =-SUMIFS('2023-04'!$M:$M,'2023-04'!$E:$E,Trésorerie!U$4,'2023-04'!$F:$F,Trésorerie!$B11)+SUMIFS('2023-04'!$N:$N,'2023-04'!$E:$E,Trésorerie!U$4,'2023-04'!$F:$F,Trésorerie!$B11) -> 0 | V11: =-SUMIFS('2023-05'!$M:$M,'2023-05'!$E:$E,Trésorerie!V$4,'2023-05'!$F:$F,Trésorerie!$B11)+SUMIFS('2023-05'!$N:$N,'2023-05'!$E:$E,Trésorerie!V$4,'2023-05'!$F:$F,Trésorerie!$B11) -> 24661 | W11: =-SUMIFS('2023-06'!$M:$M,'2023-06'!$E:$E,Trésorerie!W$4,'2023-06'!$F:$F,Trésorerie!$B11)+SUMIFS('2023-06'!$N:$N,'2023-06'!$E:$E,Trésorerie!W$4,'2023-06'!$F:$F,Trésorerie!$B11) -> 0 | X11: =-SUMIFS('2023-07'!$M:$M,'2023-07'!$E:$E,Trésorerie!X$4,'2023-07'!$F:$F,Trésorerie!$B11)+SUMIFS('2023-07'!$N:$N,'2023-07'!$E:$E,Trésorerie!X$4,'2023-07'!$F:$F,Trésorerie!$B11) -> 0 | Y11: =-SUMIFS('2023-08'!$M:$M,'2023-08'!$E:$E,Trésorerie!Y$4,'2023-08'!$F:$F,Trésorerie!$B11)+SUMIFS('2023-08'!$N:$N,'2023-08'!$E:$E,Trésorerie!Y$4,'2023-08'!$F:$F,Trésorerie!$B11) -> 6000 | Z11: =-SUMIFS('2023-09'!$M:$M,'2023-09'!$E:$E,Trésorerie!Z$4,'2023-09'!$F:$F,Trésorerie!$B11)+SUMIFS('2023-09'!$N:$N,'2023-09'!$E:$E,Trésorerie!Z$4,'2023-09'!$F:$F,Trésorerie!$B11) -> 0 | AA11: =-SUMIFS('2023-10'!$M:$M,'2023-10'!$E:$E,Trésorerie!AA$4,'2023-10'!$F:$F,Trésorerie!$B11)+SUMIFS('2023-10'!$N:$N,'2023-10'!$E:$E,Trésorerie!AA$4,'2023-10'!$F:$F,Trésorerie!$B11) -> 25630 | AB11: =IF(SUM($E11:O11)>SUM($R11:AA11),SUM($E11:O11)-SUM($R11:AA11),0) -> 49 | AC11: =IF(SUM($E11:P11)>SUM($R11:AB11),SUM($E11:P11)-SUM($R11:AB11),0) -> 0
A12: =SUM(E12:P12) -> 51000 | B12: 468730 | C12: ETAT ACSE CGET | D12: Entrée | E12: =-SUMIFS('2022'!$M:$M,'2022'!$E:$E,Trésorerie!E$4,'2022'!$F:$F,Trésorerie!$B12)+SUMIFS('2022'!$N:$N,'2022'!$E:$E,Trésorerie!E$4,'2022'!$F:$F,Trésorerie!$B12) -> 0 | F12: =-SUMIFS('2022'!$M:$M,'2022'!$E:$E,Trésorerie!F$4,'2022'!$F:$F,Trésorerie!$B12)+SUMIFS('2022'!$N:$N,'2022'!$E:$E,Trésorerie!F$4,'2022'!$F:$F,Trésorerie!$B12) -> 0 | G12: =-SUMIFS('2022'!$M:$M,'2022'!$E:$E,Trésorerie!G$4,'2022'!$F:$F,Trésorerie!$B12)+SUMIFS('2022'!$N:$N,'2022'!$E:$E,Trésorerie!G$4,'2022'!$F:$F,Trésorerie!$B12) -> 0 | H12: =-SUMIFS('2022'!$M:$M,'2022'!$E:$E,Trésorerie!H$4,'2022'!$F:$F,Trésorerie!$B12)+SUMIFS('2022'!$N:$N,'2022'!$E:$E,Trésorerie!H$4,'2022'!$F:$F,Trésorerie!$B12) -> 0 | I12: =-SUMIFS('2022'!$M:$M,'2022'!$E:$E,Trésorerie!I$4,'2022'!$F:$F,Trésorerie!$B12)+SUMIFS('2022'!$N:$N,'2022'!$E:$E,Trésorerie!I$4,'2022'!$F:$F,Trésorerie!$B12) -> 0 | J12: =-SUMIFS('2022'!$M:$M,'2022'!$E:$E,Trésorerie!J$4,'2022'!$F:$F,Trésorerie!$B12)+SUMIFS('2022'!$N:$N,'2022'!$E:$E,Trésorerie!J$4,'2022'!$F:$F,Trésorerie!$B12) -> 0 | K12: =-SUMIFS('2022'!$M:$M,'2022'!$E:$E,Trésorerie!K$4,'2022'!$F:$F,Trésorerie!$B12)+SUMIFS('2022'!$N:$N,'2022'!$E:$E,Trésorerie!K$4,'2022'!$F:$F,Trésorerie!$B12) -> 0 | L12: =-SUMIFS('2022'!$M:$M,'2022'!$E:$E,Trésorerie!L$4,'2022'!$F:$F,Trésorerie!$B12)+SUMIFS('2022'!$N:$N,'2022'!$E:$E,Trésorerie!L$4,'2022'!$F:$F,Trésorerie!$B12) -> 51000 | ... P12: =-SUMIFS('2022'!$M:$M,'2022'!$E:$E,Trésorerie!P$4,'2022'!$F:$F,Trésorerie!$B12)+SUMIFS('2022'!$N:$N,'2022'!$E:$E,Trésorerie!P$4,'2022'!$F:$F,Trésorerie!$B12) -> 0 | R12: =-SUMIFS('2023-01'!$M:$M,'2023-01'!$E:$E,Trésorerie!R$4,'2023-01'!$F:$F,Trésorerie!$B12)+SUMIFS('2023-01'!$N:$N,'2023-01'!$E:$E,Trésorerie!R$4,'2023-01'!$F:$F,Trésorerie!$B12) -> 0 | S12: =-SUMIFS('2023-02'!$M:$M,'2023-02'!$E:$E,Trésorerie!S$4,'2023-02'!$F:$F,Trésorerie!$B12)+SUMIFS('2023-02'!$N:$N,'2023-02'!$E:$E,Trésorerie!S$4,'2023-02'!$F:$F,Trésorerie!$B12) -> 0 | T12: =-SUMIFS('2023-03'!$M:$M,'2023-03'!$E:$E,Trésorerie!T$4,'2023-03'!$F:$F,Trésorerie!$B12)+SUMIFS('2023-03'!$N:$N,'2023-03'!$E:$E,Trésorerie!T$4,'2023-03'!$F:$F,Trésorerie!$B12) -> 0 | U12: =-SUMIFS('2023-04'!$M:$M,'2023-04'!$E:$E,Trésorerie!U$4,'2023-04'!$F:$F,Trésorerie!$B12)+SUMIFS('2023-04'!$N:$N,'2023-04'!$E:$E,Trésorerie!U$4,'2023-04'!$F:$F,Trésorerie!$B12) -> 0 | V12: =-SUMIFS('2023-05'!$M:$M,'2023-05'!$E:$E,Trésorerie!V$4,'2023-05'!$F:$F,Trésorerie!$B12)+SUMIFS('2023-05'!$N:$N,'2023-05'!$E:$E,Trésorerie!V$4,'2023-05'!$F:$F,Trésorerie!$B12) -> 0 | W12: =-SUMIFS('2023-06'!$M:$M,'2023-06'!$E:$E,Trésorerie!W$4,'2023-06'!$F:$F,Trésorerie!$B12)+SUMIFS('2023-06'!$N:$N,'2023-06'!$E:$E,Trésorerie!W$4,'2023-06'!$F:$F,Trésorerie!$B12) -> 0 | X12: =-SUMIFS('2023-07'!$M:$M,'2023-07'!$E:$E,Trésorerie!X$4,'2023-07'!$F:$F,Trésorerie!$B12)+SUMIFS('2023-07'!$N:$N,'2023-07'!$E:$E,Trésorerie!X$4,'2023-07'!$F:$F,Trésorerie!$B12) -> 43000 | Y12: =-SUMIFS('2023-08'!$M:$M,'2023-08'!$E:$E,Trésorerie!Y$4,'2023-08'!$F:$F,Trésorerie!$B12)+SUMIFS('2023-08'!$N:$N,'2023-08'!$E:$E,Trésorerie!Y$4,'2023-08'!$F:$F,Trésorerie!$B12) -> 4500 | Z12: =-SUMIFS('2023-09'!$M:$M,'2023-09'!$E:$E,Trésorerie!Z$4,'2023-09'!$F:$F,Trésorerie!$B12)+SUMIFS('2023-09'!$N:$N,'2023-09'!$E:$E,Trésorerie!Z$4,'2023-09'!$F:$F,Trésorerie!$B12) -> 0 | AA12: =-SUMIFS('2023-10'!$M:$M,'2023-10'!$E:$E,Trésorerie!AA$4,'2023-10'!$F:$F,Trésorerie!$B12)+SUMIFS('2023-10'!$N:$N,'2023-10'!$E:$E,Trésorerie!AA$4,'2023-10'!$F:$F,Trésorerie!$B12) -> 666.6 | AB12: =IF(SUM($E12:O12)>SUM($R12:AA12),SUM($E12:O12)-SUM($R12:AA12),0) -> 2833.4 | AC12: =IF(SUM($E12:P12)>SUM($R12:AB12),SUM($E12:P12)-SUM($R12:AB12),0) -> 0
A13: =SUM(E13:P13) -> 47294 | B13: 445051 | C13: CAF ACF | D13: Entrée | E13: =-SUMIFS('2022'!$M:$M,'2022'!$E:$E,Trésorerie!E$4,'2022'!$F:$F,Trésorerie!$B13)+SUMIFS('2022'!$N:$N,'2022'!$E:$E,Trésorerie!E$4,'2022'!$F:$F,Trésorerie!$B13) -> 0 | F13: =-SUMIFS('2022'!$M:$M,'2022'!$E:$E,Trésorerie!F$4,'2022'!$F:$F,Trésorerie!$B13)+SUMIFS('2022'!$N:$N,'2022'!$E:$E,Trésorerie!F$4,'2022'!$F:$F,Trésorerie!$B13) -> 0 | G13: =-SUMIFS('2022'!$M:$M,'2022'!$E:$E,Trésorerie!G$4,'2022'!$F:$F,Trésorerie!$B13)+SUMIFS('2022'!$N:$N,'2022'!$E:$E,Trésorerie!G$4,'2022'!$F:$F,Trésorerie!$B13) -> 21313.8 | H13: =-SUMIFS('2022'!$M:$M,'2022'!$E:$E,Trésorerie!H$4,'2022'!$F:$F,Trésorerie!$B13)+SUMIFS('2022'!$N:$N,'2022'!$E:$E,Trésorerie!H$4,'2022'!$F:$F,Trésorerie!$B13) -> 0 | I13: =-SUMIFS('2022'!$M:$M,'2022'!$E:$E,Trésorerie!I$4,'2022'!$F:$F,Trésorerie!$B13)+SUMIFS('2022'!$N:$N,'2022'!$E:$E,Trésorerie!I$4,'2022'!$F:$F,Trésorerie!$B13) -> 4666.4 | J13: =-SUMIFS('2022'!$M:$M,'2022'!$E:$E,Trésorerie!J$4,'2022'!$F:$F,Trésorerie!$B13)+SUMIFS('2022'!$N:$N,'2022'!$E:$E,Trésorerie!J$4,'2022'!$F:$F,Trésorerie!$B13) -> 0 | K13: =-SUMIFS('2022'!$M:$M,'2022'!$E:$E,Trésorerie!K$4,'2022'!$F:$F,Trésorerie!$B13)+SUMIFS('2022'!$N:$N,'2022'!$E:$E,Trésorerie!K$4,'2022'!$F:$F,Trésorerie!$B13) -> 0 | L13: =-SUMIFS('2022'!$M:$M,'2022'!$E:$E,Trésorerie!L$4,'2022'!$F:$F,Trésorerie!$B13)+SUMIFS('2022'!$N:$N,'2022'!$E:$E,Trésorerie!L$4,'2022'!$F:$F,Trésorerie!$B13) -> 0 | ... P13: =-SUMIFS('2022'!$M:$M,'2022'!$E:$E,Trésorerie!P$4,'2022'!$F:$F,Trésorerie!$B13)+SUMIFS('2022'!$N:$N,'2022'!$E:$E,Trésorerie!P$4,'2022'!$F:$F,Trésorerie!$B13) -> 0 | R13: =-SUMIFS('2023-01'!$M:$M,'2023-01'!$E:$E,Trésorerie!R$4,'2023-01'!$F:$F,Trésorerie!$B13)+SUMIFS('2023-01'!$N:$N,'2023-01'!$E:$E,Trésorerie!R$4,'2023-01'!$F:$F,Trésorerie!$B13) -> 0 | S13: =-SUMIFS('2023-02'!$M:$M,'2023-02'!$E:$E,Trésorerie!S$4,'2023-02'!$F:$F,Trésorerie!$B13)+SUMIFS('2023-02'!$N:$N,'2023-02'!$E:$E,Trésorerie!S$4,'2023-02'!$F:$F,Trésorerie!$B13) -> 0 | T13: =-SUMIFS('2023-03'!$M:$M,'2023-03'!$E:$E,Trésorerie!T$4,'2023-03'!$F:$F,Trésorerie!$B13)+SUMIFS('2023-03'!$N:$N,'2023-03'!$E:$E,Trésorerie!T$4,'2023-03'!$F:$F,Trésorerie!$B13) -> 20632.68 | U13: =-SUMIFS('2023-04'!$M:$M,'2023-04'!$E:$E,Trésorerie!U$4,'2023-04'!$F:$F,Trésorerie!$B13)+SUMIFS('2023-04'!$N:$N,'2023-04'!$E:$E,Trésorerie!U$4,'2023-04'!$F:$F,Trésorerie!$B13) -> 0 | V13: =-SUMIFS('2023-05'!$M:$M,'2023-05'!$E:$E,Trésorerie!V$4,'2023-05'!$F:$F,Trésorerie!$B13)+SUMIFS('2023-05'!$N:$N,'2023-05'!$E:$E,Trésorerie!V$4,'2023-05'!$F:$F,Trésorerie!$B13) -> 0 | W13: =-SUMIFS('2023-06'!$M:$M,'2023-06'!$E:$E,Trésorerie!W$4,'2023-06'!$F:$F,Trésorerie!$B13)+SUMIFS('2023-06'!$N:$N,'2023-06'!$E:$E,Trésorerie!W$4,'2023-06'!$F:$F,Trésorerie!$B13) -> 0 | X13: =-SUMIFS('2023-07'!$M:$M,'2023-07'!$E:$E,Trésorerie!X$4,'2023-07'!$F:$F,Trésorerie!$B13)+SUMIFS('2023-07'!$N:$N,'2023-07'!$E:$E,Trésorerie!X$4,'2023-07'!$F:$F,Trésorerie!$B13) -> 0 | Y13: =-SUMIFS('2023-08'!$M:$M,'2023-08'!$E:$E,Trésorerie!Y$4,'2023-08'!$F:$F,Trésorerie!$B13)+SUMIFS('2023-08'!$N:$N,'2023-08'!$E:$E,Trésorerie!Y$4,'2023-08'!$F:$F,Trésorerie!$B13) -> 0 | Z13: =-SUMIFS('2023-09'!$M:$M,'2023-09'!$E:$E,Trésorerie!Z$4,'2023-09'!$F:$F,Trésorerie!$B13)+SUMIFS('2023-09'!$N:$N,'2023-09'!$E:$E,Trésorerie!Z$4,'2023-09'!$F:$F,Trésorerie!$B13) -> 0 | AA13: =-SUMIFS('2023-10'!$M:$M,'2023-10'!$E:$E,Trésorerie!AA$4,'2023-10'!$F:$F,Trésorerie!$B13)+SUMIFS('2023-10'!$N:$N,'2023-10'!$E:$E,Trésorerie!AA$4,'2023-10'!$F:$F,Trésorerie!$B13) -> 20632.68 | AB13: =IF(SUM($E13:O13)>SUM($R13:AA13),SUM($E13:O13)-SUM($R13:AA13),0) -> 6028.64 | AC13: =IF(SUM($E13:P13)>SUM($R13:AB13),SUM($E13:P13)-SUM($R13:AB13),0) -> 0
A14: =SUM(E14:P14) -> 38494.29 | B14: 468200 | C14: INDEMN.JOURNAL. A RECEVOIR | D14: Entrée | E14: =-SUMIFS('2022'!$M:$M,'2022'!$E:$E,Trésorerie!E$4,'2022'!$F:$F,Trésorerie!$B14)+SUMIFS('2022'!$N:$N,'2022'!$E:$E,Trésorerie!E$4,'2022'!$F:$F,Trésorerie!$B14) -> 2980.91 | F14: =-SUMIFS('2022'!$M:$M,'2022'!$E:$E,Trésorerie!F$4,'2022'!$F:$F,Trésorerie!$B14)+SUMIFS('2022'!$N:$N,'2022'!$E:$E,Trésorerie!F$4,'2022'!$F:$F,Trésorerie!$B14) -> 2585.36 | G14: =-SUMIFS('2022'!$M:$M,'2022'!$E:$E,Trésorerie!G$4,'2022'!$F:$F,Trésorerie!$B14)+SUMIFS('2022'!$N:$N,'2022'!$E:$E,Trésorerie!G$4,'2022'!$F:$F,Trésorerie!$B14) -> 1030.5 | H14: =-SUMIFS('2022'!$M:$M,'2022'!$E:$E,Trésorerie!H$4,'2022'!$F:$F,Trésorerie!$B14)+SUMIFS('2022'!$N:$N,'2022'!$E:$E,Trésorerie!H$4,'2022'!$F:$F,Trésorerie!$B14) -> 1879.11 | I14: =-SUMIFS('2022'!$M:$M,'2022'!$E:$E,Trésorerie!I$4,'2022'!$F:$F,Trésorerie!$B14)+SUMIFS('2022'!$N:$N,'2022'!$E:$E,Trésorerie!I$4,'2022'!$F:$F,Trésorerie!$B14) -> 6227.46 | J14: =-SUMIFS('2022'!$M:$M,'2022'!$E:$E,Trésorerie!J$4,'2022'!$F:$F,Trésorerie!$B14)+SUMIFS('2022'!$N:$N,'2022'!$E:$E,Trésorerie!J$4,'2022'!$F:$F,Trésorerie!$B14) -> 2199.56 | K14: =-SUMIFS('2022'!$M:$M,'2022'!$E:$E,Trésorerie!K$4,'2022'!$F:$F,Trésorerie!$B14)+SUMIFS('2022'!$N:$N,'2022'!$E:$E,Trésorerie!K$4,'2022'!$F:$F,Trésorerie!$B14) -> 878.92 | L14: =-SUMIFS('2022'!$M:$M,'2022'!$E:$E,Trésorerie!L$4,'2022'!$F:$F,Trésorerie!$B14)+SUMIFS('2022'!$N:$N,'2022'!$E:$E,Trésorerie!L$4,'2022'!$F:$F,Trésorerie!$B14) -> 3571.15 | ... P14: =-SUMIFS('2022'!$M:$M,'2022'!$E:$E,Trésorerie!P$4,'2022'!$F:$F,Trésorerie!$B14)+SUMIFS('2022'!$N:$N,'2022'!$E:$E,Trésorerie!P$4,'2022'!$F:$F,Trésorerie!$B14) -> 888.28 | R14: =-SUMIFS('2023-01'!$M:$M,'2023-01'!$E:$E,Trésorerie!R$4,'2023-01'!$F:$F,Trésorerie!$B14)+SUMIFS('2023-01'!$N:$N,'2023-01'!$E:$E,Trésorerie!R$4,'2023-01'!$F:$F,Trésorerie!$B14) -> 290.76 | S14: =-SUMIFS('2023-02'!$M:$M,'2023-02'!$E:$E,Trésorerie!S$4,'2023-02'!$F:$F,Trésorerie!$B14)+SUMIFS('2023-02'!$N:$N,'2023-02'!$E:$E,Trésorerie!S$4,'2023-02'!$F:$F,Trésorerie!$B14) -> 2046.45 | T14: =-SUMIFS('2023-03'!$M:$M,'2023-03'!$E:$E,Trésorerie!T$4,'2023-03'!$F:$F,Trésorerie!$B14)+SUMIFS('2023-03'!$N:$N,'2023-03'!$E:$E,Trésorerie!T$4,'2023-03'!$F:$F,Trésorerie!$B14) -> 3402.87 | U14: =-SUMIFS('2023-04'!$M:$M,'2023-04'!$E:$E,Trésorerie!U$4,'2023-04'!$F:$F,Trésorerie!$B14)+SUMIFS('2023-04'!$N:$N,'2023-04'!$E:$E,Trésorerie!U$4,'2023-04'!$F:$F,Trésorerie!$B14) -> 2414.05 | V14: =-SUMIFS('2023-05'!$M:$M,'2023-05'!$E:$E,Trésorerie!V$4,'2023-05'!$F:$F,Trésorerie!$B14)+SUMIFS('2023-05'!$N:$N,'2023-05'!$E:$E,Trésorerie!V$4,'2023-05'!$F:$F,Trésorerie!$B14) -> 953.48 | W14: =-SUMIFS('2023-06'!$M:$M,'2023-06'!$E:$E,Trésorerie!W$4,'2023-06'!$F:$F,Trésorerie!$B14)+SUMIFS('2023-06'!$N:$N,'2023-06'!$E:$E,Trésorerie!W$4,'2023-06'!$F:$F,Trésorerie!$B14) -> 2874.48 | X14: =-SUMIFS('2023-07'!$M:$M,'2023-07'!$E:$E,Trésorerie!X$4,'2023-07'!$F:$F,Trésorerie!$B14)+SUMIFS('2023-07'!$N:$N,'2023-07'!$E:$E,Trésorerie!X$4,'2023-07'!$F:$F,Trésorerie!$B14) -> 2138.07 | Y14: =-SUMIFS('2023-08'!$M:$M,'2023-08'!$E:$E,Trésorerie!Y$4,'2023-08'!$F:$F,Trésorerie!$B14)+SUMIFS('2023-08'!$N:$N,'2023-08'!$E:$E,Trésorerie!Y$4,'2023-08'!$F:$F,Trésorerie!$B14) -> 818.96 | Z14: =-SUMIFS('2023-09'!$M:$M,'2023-09'!$E:$E,Trésorerie!Z$4,'2023-09'!$F:$F,Trésorerie!$B14)+SUMIFS('2023-09'!$N:$N,'2023-09'!$E:$E,Trésorerie!Z$4,'2023-09'!$F:$F,Trésorerie!$B14) -> 1006.45 | AA14: =-SUMIFS('2023-10'!$M:$M,'2023-10'!$E:$E,Trésorerie!AA$4,'2023-10'!$F:$F,Trésorerie!$B14)+SUMIFS('2023-10'!$N:$N,'2023-10'!$E:$E,Trésorerie!AA$4,'2023-10'!$F:$F,Trésorerie!$B14) -> 8507.24 | AB14: =IF(SUM($E14:O14)>SUM($R14:AA14),SUM($E14:O14)-SUM($R14:AA14),0) -> 13153.2 | AC14: =IF(SUM($E14:P14)>SUM($R14:AB14),SUM($E14:P14)-SUM($R14:AB14),0) -> 888.28
A15: =SUM(E15:P15) -> 32172 | B15: 445000 | C15: CAF PS AL EXTRASCO CYP CFAL | D15: Entrée | E15: =-SUMIFS('2022'!$M:$M,'2022'!$E:$E,Trésorerie!E$4,'2022'!$F:$F,Trésorerie!$B15)+SUMIFS('2022'!$N:$N,'2022'!$E:$E,Trésorerie!E$4,'2022'!$F:$F,Trésorerie!$B15) -> 0 | F15: =-SUMIFS('2022'!$M:$M,'2022'!$E:$E,Trésorerie!F$4,'2022'!$F:$F,Trésorerie!$B15)+SUMIFS('2022'!$N:$N,'2022'!$E:$E,Trésorerie!F$4,'2022'!$F:$F,Trésorerie!$B15) -> 0 | G15: =-SUMIFS('2022'!$M:$M,'2022'!$E:$E,Trésorerie!G$4,'2022'!$F:$F,Trésorerie!$B15)+SUMIFS('2022'!$N:$N,'2022'!$E:$E,Trésorerie!G$4,'2022'!$F:$F,Trésorerie!$B15) -> 0 | H15: =-SUMIFS('2022'!$M:$M,'2022'!$E:$E,Trésorerie!H$4,'2022'!$F:$F,Trésorerie!$B15)+SUMIFS('2022'!$N:$N,'2022'!$E:$E,Trésorerie!H$4,'2022'!$F:$F,Trésorerie!$B15) -> 0 | I15: =-SUMIFS('2022'!$M:$M,'2022'!$E:$E,Trésorerie!I$4,'2022'!$F:$F,Trésorerie!$B15)+SUMIFS('2022'!$N:$N,'2022'!$E:$E,Trésorerie!I$4,'2022'!$F:$F,Trésorerie!$B15) -> 10692.8 | J15: =-SUMIFS('2022'!$M:$M,'2022'!$E:$E,Trésorerie!J$4,'2022'!$F:$F,Trésorerie!$B15)+SUMIFS('2022'!$N:$N,'2022'!$E:$E,Trésorerie!J$4,'2022'!$F:$F,Trésorerie!$B15) -> 14973.48 | K15: =-SUMIFS('2022'!$M:$M,'2022'!$E:$E,Trésorerie!K$4,'2022'!$F:$F,Trésorerie!$B15)+SUMIFS('2022'!$N:$N,'2022'!$E:$E,Trésorerie!K$4,'2022'!$F:$F,Trésorerie!$B15) -> 0 | L15: =-SUMIFS('2022'!$M:$M,'2022'!$E:$E,Trésorerie!L$4,'2022'!$F:$F,Trésorerie!$B15)+SUMIFS('2022'!$N:$N,'2022'!$E:$E,Trésorerie!L$4,'2022'!$F:$F,Trésorerie!$B15) -> 0 | ... P15: =-SUMIFS('2022'!$M:$M,'2022'!$E:$E,Trésorerie!P$4,'2022'!$F:$F,Trésorerie!$B15)+SUMIFS('2022'!$N:$N,'2022'!$E:$E,Trésorerie!P$4,'2022'!$F:$F,Trésorerie!$B15) -> 0 | R15: =-SUMIFS('2023-01'!$M:$M,'2023-01'!$E:$E,Trésorerie!R$4,'2023-01'!$F:$F,Trésorerie!$B15)+SUMIFS('2023-01'!$N:$N,'2023-01'!$E:$E,Trésorerie!R$4,'2023-01'!$F:$F,Trésorerie!$B15) -> 0 | S15: =-SUMIFS('2023-02'!$M:$M,'2023-02'!$E:$E,Trésorerie!S$4,'2023-02'!$F:$F,Trésorerie!$B15)+SUMIFS('2023-02'!$N:$N,'2023-02'!$E:$E,Trésorerie!S$4,'2023-02'!$F:$F,Trésorerie!$B15) -> 0 | T15: =-SUMIFS('2023-03'!$M:$M,'2023-03'!$E:$E,Trésorerie!T$4,'2023-03'!$F:$F,Trésorerie!$B15)+SUMIFS('2023-03'!$N:$N,'2023-03'!$E:$E,Trésorerie!T$4,'2023-03'!$F:$F,Trésorerie!$B15) -> 14695.16 | U15: =-SUMIFS('2023-04'!$M:$M,'2023-04'!$E:$E,Trésorerie!U$4,'2023-04'!$F:$F,Trésorerie!$B15)+SUMIFS('2023-04'!$N:$N,'2023-04'!$E:$E,Trésorerie!U$4,'2023-04'!$F:$F,Trésorerie!$B15) -> 0 | V15: =-SUMIFS('2023-05'!$M:$M,'2023-05'!$E:$E,Trésorerie!V$4,'2023-05'!$F:$F,Trésorerie!$B15)+SUMIFS('2023-05'!$N:$N,'2023-05'!$E:$E,Trésorerie!V$4,'2023-05'!$F:$F,Trésorerie!$B15) -> 0 | W15: =-SUMIFS('2023-06'!$M:$M,'2023-06'!$E:$E,Trésorerie!W$4,'2023-06'!$F:$F,Trésorerie!$B15)+SUMIFS('2023-06'!$N:$N,'2023-06'!$E:$E,Trésorerie!W$4,'2023-06'!$F:$F,Trésorerie!$B15) -> 6291.27 | X15: =-SUMIFS('2023-07'!$M:$M,'2023-07'!$E:$E,Trésorerie!X$4,'2023-07'!$F:$F,Trésorerie!$B15)+SUMIFS('2023-07'!$N:$N,'2023-07'!$E:$E,Trésorerie!X$4,'2023-07'!$F:$F,Trésorerie!$B15) -> 0 | Y15: =-SUMIFS('2023-08'!$M:$M,'2023-08'!$E:$E,Trésorerie!Y$4,'2023-08'!$F:$F,Trésorerie!$B15)+SUMIFS('2023-08'!$N:$N,'2023-08'!$E:$E,Trésorerie!Y$4,'2023-08'!$F:$F,Trésorerie!$B15) -> 0 | Z15: =-SUMIFS('2023-09'!$M:$M,'2023-09'!$E:$E,Trésorerie!Z$4,'2023-09'!$F:$F,Trésorerie!$B15)+SUMIFS('2023-09'!$N:$N,'2023-09'!$E:$E,Trésorerie!Z$4,'2023-09'!$F:$F,Trésorerie!$B15) -> 6111.21 | AA15: =-SUMIFS('2023-10'!$M:$M,'2023-10'!$E:$E,Trésorerie!AA$4,'2023-10'!$F:$F,Trésorerie!$B15)+SUMIFS('2023-10'!$N:$N,'2023-10'!$E:$E,Trésorerie!AA$4,'2023-10'!$F:$F,Trésorerie!$B15) -> 0 | AB15: =IF(SUM($E15:O15)>SUM($R15:AA15),SUM($E15:O15)-SUM($R15:AA15),0) -> 5074.36 | AC15: =IF(SUM($E15:P15)>SUM($R15:AB15),SUM($E15:P15)-SUM($R15:AB15),0) -> 0
A16: =SUM(E16:P16) -> 29719.63 | B16: 411100 | C16: COMPTE GESTION ADHERENTS | D16: Entrée | E16: =-SUMIFS('2022'!$M:$M,'2022'!$E:$E,Trésorerie!E$4,'2022'!$F:$F,Trésorerie!$B16)+SUMIFS('2022'!$N:$N,'2022'!$E:$E,Trésorerie!E$4,'2022'!$F:$F,Trésorerie!$B16) -> 2108.45 | F16: =-SUMIFS('2022'!$M:$M,'2022'!$E:$E,Trésorerie!F$4,'2022'!$F:$F,Trésorerie!$B16)+SUMIFS('2022'!$N:$N,'2022'!$E:$E,Trésorerie!F$4,'2022'!$F:$F,Trésorerie!$B16) -> 2682.07 | G16: =-SUMIFS('2022'!$M:$M,'2022'!$E:$E,Trésorerie!G$4,'2022'!$F:$F,Trésorerie!$B16)+SUMIFS('2022'!$N:$N,'2022'!$E:$E,Trésorerie!G$4,'2022'!$F:$F,Trésorerie!$B16) -> 2694.17 | H16: =-SUMIFS('2022'!$M:$M,'2022'!$E:$E,Trésorerie!H$4,'2022'!$F:$F,Trésorerie!$B16)+SUMIFS('2022'!$N:$N,'2022'!$E:$E,Trésorerie!H$4,'2022'!$F:$F,Trésorerie!$B16) -> 2398.68 | I16: =-SUMIFS('2022'!$M:$M,'2022'!$E:$E,Trésorerie!I$4,'2022'!$F:$F,Trésorerie!$B16)+SUMIFS('2022'!$N:$N,'2022'!$E:$E,Trésorerie!I$4,'2022'!$F:$F,Trésorerie!$B16) -> 1550.78 | J16: =-SUMIFS('2022'!$M:$M,'2022'!$E:$E,Trésorerie!J$4,'2022'!$F:$F,Trésorerie!$B16)+SUMIFS('2022'!$N:$N,'2022'!$E:$E,Trésorerie!J$4,'2022'!$F:$F,Trésorerie!$B16) -> 3974.71 | K16: =-SUMIFS('2022'!$M:$M,'2022'!$E:$E,Trésorerie!K$4,'2022'!$F:$F,Trésorerie!$B16)+SUMIFS('2022'!$N:$N,'2022'!$E:$E,Trésorerie!K$4,'2022'!$F:$F,Trésorerie!$B16) -> 2352.48 | L16: =-SUMIFS('2022'!$M:$M,'2022'!$E:$E,Trésorerie!L$4,'2022'!$F:$F,Trésorerie!$B16)+SUMIFS('2022'!$N:$N,'2022'!$E:$E,Trésorerie!L$4,'2022'!$F:$F,Trésorerie!$B16) -> 348.89 | ... P16: =-SUMIFS('2022'!$M:$M,'2022'!$E:$E,Trésorerie!P$4,'2022'!$F:$F,Trésorerie!$B16)+SUMIFS('2022'!$N:$N,'2022'!$E:$E,Trésorerie!P$4,'2022'!$F:$F,Trésorerie!$B16) -> 1070.39 | R16: =-SUMIFS('2023-01'!$M:$M,'2023-01'!$E:$E,Trésorerie!R$4,'2023-01'!$F:$F,Trésorerie!$B16)+SUMIFS('2023-01'!$N:$N,'2023-01'!$E:$E,Trésorerie!R$4,'2023-01'!$F:$F,Trésorerie!$B16) -> 4197.01 | S16: =-SUMIFS('2023-02'!$M:$M,'2023-02'!$E:$E,Trésorerie!S$4,'2023-02'!$F:$F,Trésorerie!$B16)+SUMIFS('2023-02'!$N:$N,'2023-02'!$E:$E,Trésorerie!S$4,'2023-02'!$F:$F,Trésorerie!$B16) -> 2177.34 | T16: =-SUMIFS('2023-03'!$M:$M,'2023-03'!$E:$E,Trésorerie!T$4,'2023-03'!$F:$F,Trésorerie!$B16)+SUMIFS('2023-03'!$N:$N,'2023-03'!$E:$E,Trésorerie!T$4,'2023-03'!$F:$F,Trésorerie!$B16) -> 4485.05 | U16: =-SUMIFS('2023-04'!$M:$M,'2023-04'!$E:$E,Trésorerie!U$4,'2023-04'!$F:$F,Trésorerie!$B16)+SUMIFS('2023-04'!$N:$N,'2023-04'!$E:$E,Trésorerie!U$4,'2023-04'!$F:$F,Trésorerie!$B16) -> 2003.89 | V16: =-SUMIFS('2023-05'!$M:$M,'2023-05'!$E:$E,Trésorerie!V$4,'2023-05'!$F:$F,Trésorerie!$B16)+SUMIFS('2023-05'!$N:$N,'2023-05'!$E:$E,Trésorerie!V$4,'2023-05'!$F:$F,Trésorerie!$B16) -> 1651.04 | W16: =-SUMIFS('2023-06'!$M:$M,'2023-06'!$E:$E,Trésorerie!W$4,'2023-06'!$F:$F,Trésorerie!$B16)+SUMIFS('2023-06'!$N:$N,'2023-06'!$E:$E,Trésorerie!W$4,'2023-06'!$F:$F,Trésorerie!$B16) -> 5835.53 | X16: =-SUMIFS('2023-07'!$M:$M,'2023-07'!$E:$E,Trésorerie!X$4,'2023-07'!$F:$F,Trésorerie!$B16)+SUMIFS('2023-07'!$N:$N,'2023-07'!$E:$E,Trésorerie!X$4,'2023-07'!$F:$F,Trésorerie!$B16) -> 3291.56 | Y16: =-SUMIFS('2023-08'!$M:$M,'2023-08'!$E:$E,Trésorerie!Y$4,'2023-08'!$F:$F,Trésorerie!$B16)+SUMIFS('2023-08'!$N:$N,'2023-08'!$E:$E,Trésorerie!Y$4,'2023-08'!$F:$F,Trésorerie!$B16) -> 735.86 | Z16: =-SUMIFS('2023-09'!$M:$M,'2023-09'!$E:$E,Trésorerie!Z$4,'2023-09'!$F:$F,Trésorerie!$B16)+SUMIFS('2023-09'!$N:$N,'2023-09'!$E:$E,Trésorerie!Z$4,'2023-09'!$F:$F,Trésorerie!$B16) -> 4975.37 | AA16: =-SUMIFS('2023-10'!$M:$M,'2023-10'!$E:$E,Trésorerie!AA$4,'2023-10'!$F:$F,Trésorerie!$B16)+SUMIFS('2023-10'!$N:$N,'2023-10'!$E:$E,Trésorerie!AA$4,'2023-10'!$F:$F,Trésorerie!$B16) -> 5709 | AB16: =IF(SUM($E16:O16)>SUM($R16:AA16),SUM($E16:O16)-SUM($R16:AA16),0) -> 0 | AC16: =IF(SUM($E16:P16)>SUM($R16:AB16),SUM($E16:P16)-SUM($R16:AB16),0) -> 0
... A18: =SUM(E18:P18) -> 26900 | B18: 445057 | C18: CAF AUTRES SUBVENTIONS | D18: Entrée | E18: =-SUMIFS('2022'!$M:$M,'2022'!$E:$E,Trésorerie!E$4,'2022'!$F:$F,Trésorerie!$B18)+SUMIFS('2022'!$N:$N,'2022'!$E:$E,Trésorerie!E$4,'2022'!$F:$F,Trésorerie!$B18) -> 0 | F18: =-SUMIFS('2022'!$M:$M,'2022'!$E:$E,Trésorerie!F$4,'2022'!$F:$F,Trésorerie!$B18)+SUMIFS('2022'!$N:$N,'2022'!$E:$E,Trésorerie!F$4,'2022'!$F:$F,Trésorerie!$B18) -> 0 | G18: =-SUMIFS('2022'!$M:$M,'2022'!$E:$E,Trésorerie!G$4,'2022'!$F:$F,Trésorerie!$B18)+SUMIFS('2022'!$N:$N,'2022'!$E:$E,Trésorerie!G$4,'2022'!$F:$F,Trésorerie!$B18) -> 0 | H18: =-SUMIFS('2022'!$M:$M,'2022'!$E:$E,Trésorerie!H$4,'2022'!$F:$F,Trésorerie!$B18)+SUMIFS('2022'!$N:$N,'2022'!$E:$E,Trésorerie!H$4,'2022'!$F:$F,Trésorerie!$B18) -> 6900 | I18: =-SUMIFS('2022'!$M:$M,'2022'!$E:$E,Trésorerie!I$4,'2022'!$F:$F,Trésorerie!$B18)+SUMIFS('2022'!$N:$N,'2022'!$E:$E,Trésorerie!I$4,'2022'!$F:$F,Trésorerie!$B18) -> 0 | J18: =-SUMIFS('2022'!$M:$M,'2022'!$E:$E,Trésorerie!J$4,'2022'!$F:$F,Trésorerie!$B18)+SUMIFS('2022'!$N:$N,'2022'!$E:$E,Trésorerie!J$4,'2022'!$F:$F,Trésorerie!$B18) -> 0 | K18: =-SUMIFS('2022'!$M:$M,'2022'!$E:$E,Trésorerie!K$4,'2022'!$F:$F,Trésorerie!$B18)+SUMIFS('2022'!$N:$N,'2022'!$E:$E,Trésorerie!K$4,'2022'!$F:$F,Trésorerie!$B18) -> 20000 | L18: =-SUMIFS('2022'!$M:$M,'2022'!$E:$E,Trésorerie!L$4,'2022'!$F:$F,Trésorerie!$B18)+SUMIFS('2022'!$N:$N,'2022'!$E:$E,Trésorerie!L$4,'2022'!$F:$F,Trésorerie!$B18) -> 0 | ... P18: =-SUMIFS('2022'!$M:$M,'2022'!$E:$E,Trésorerie!P$4,'2022'!$F:$F,Trésorerie!$B18)+SUMIFS('2022'!$N:$N,'2022'!$E:$E,Trésorerie!P$4,'2022'!$F:$F,Trésorerie!$B18) -> 0 | R18: =-SUMIFS('2023-01'!$M:$M,'2023-01'!$E:$E,Trésorerie!R$4,'2023-01'!$F:$F,Trésorerie!$B18)+SUMIFS('2023-01'!$N:$N,'2023-01'!$E:$E,Trésorerie!R$4,'2023-01'!$F:$F,Trésorerie!$B18) -> 0 | S18: =-SUMIFS('2023-02'!$M:$M,'2023-02'!$E:$E,Trésorerie!S$4,'2023-02'!$F:$F,Trésorerie!$B18)+SUMIFS('2023-02'!$N:$N,'2023-02'!$E:$E,Trésorerie!S$4,'2023-02'!$F:$F,Trésorerie!$B18) -> 0 | T18: =-SUMIFS('2023-03'!$M:$M,'2023-03'!$E:$E,Trésorerie!T$4,'2023-03'!$F:$F,Trésorerie!$B18)+SUMIFS('2023-03'!$N:$N,'2023-03'!$E:$E,Trésorerie!T$4,'2023-03'!$F:$F,Trésorerie!$B18) -> 0 | U18: =-SUMIFS('2023-04'!$M:$M,'2023-04'!$E:$E,Trésorerie!U$4,'2023-04'!$F:$F,Trésorerie!$B18)+SUMIFS('2023-04'!$N:$N,'2023-04'!$E:$E,Trésorerie!U$4,'2023-04'!$F:$F,Trésorerie!$B18) -> 0 | V18: =-SUMIFS('2023-05'!$M:$M,'2023-05'!$E:$E,Trésorerie!V$4,'2023-05'!$F:$F,Trésorerie!$B18)+SUMIFS('2023-05'!$N:$N,'2023-05'!$E:$E,Trésorerie!V$4,'2023-05'!$F:$F,Trésorerie!$B18) -> 0 | W18: =-SUMIFS('2023-06'!$M:$M,'2023-06'!$E:$E,Trésorerie!W$4,'2023-06'!$F:$F,Trésorerie!$B18)+SUMIFS('2023-06'!$N:$N,'2023-06'!$E:$E,Trésorerie!W$4,'2023-06'!$F:$F,Trésorerie!$B18) -> 0 | X18: =-SUMIFS('2023-07'!$M:$M,'2023-07'!$E:$E,Trésorerie!X$4,'2023-07'!$F:$F,Trésorerie!$B18)+SUMIFS('2023-07'!$N:$N,'2023-07'!$E:$E,Trésorerie!X$4,'2023-07'!$F:$F,Trésorerie!$B18) -> 0 | Y18: =-SUMIFS('2023-08'!$M:$M,'2023-08'!$E:$E,Trésorerie!Y$4,'2023-08'!$F:$F,Trésorerie!$B18)+SUMIFS('2023-08'!$N:$N,'2023-08'!$E:$E,Trésorerie!Y$4,'2023-08'!$F:$F,Trésorerie!$B18) -> 0 | Z18: =-SUMIFS('2023-09'!$M:$M,'2023-09'!$E:$E,Trésorerie!Z$4,'2023-09'!$F:$F,Trésorerie!$B18)+SUMIFS('2023-09'!$N:$N,'2023-09'!$E:$E,Trésorerie!Z$4,'2023-09'!$F:$F,Trésorerie!$B18) -> 0 | AA18: =-SUMIFS('2023-10'!$M:$M,'2023-10'!$E:$E,Trésorerie!AA$4,'2023-10'!$F:$F,Trésorerie!$B18)+SUMIFS('2023-10'!$N:$N,'2023-10'!$E:$E,Trésorerie!AA$4,'2023-10'!$F:$F,Trésorerie!$B18) -> 0 | AB18: =IF(SUM($E18:O18)>SUM($R18:AA18),SUM($E18:O18)-SUM($R18:AA18),0) -> 26900 | AC18: =IF(SUM($E18:P18)>SUM($R18:AB18),SUM($E18:P18)-SUM($R18:AB18),0) -> 0
A19: 0 | B19: 445040 | C19: CAF CTG | D19: Entrée | E19: 0 | F19: 0 | G19: 0 | H19: 0 | I19: 0 | J19: 0 | K19: 0 | L19: 0 | M19: 0 | N19: 0 | O19: 0 | P19: 0 | R19: =-SUMIFS('2023-01'!$M:$M,'2023-01'!$E:$E,Trésorerie!R$4,'2023-01'!$F:$F,Trésorerie!$B19)+SUMIFS('2023-01'!$N:$N,'2023-01'!$E:$E,Trésorerie!R$4,'2023-01'!$F:$F,Trésorerie!$B19) -> 0 | S19: =-SUMIFS('2023-02'!$M:$M,'2023-02'!$E:$E,Trésorerie!S$4,'2023-02'!$F:$F,Trésorerie!$B19)+SUMIFS('2023-02'!$N:$N,'2023-02'!$E:$E,Trésorerie!S$4,'2023-02'!$F:$F,Trésorerie!$B19) -> 0 | T19: =-SUMIFS('2023-03'!$M:$M,'2023-03'!$E:$E,Trésorerie!T$4,'2023-03'!$F:$F,Trésorerie!$B19)+SUMIFS('2023-03'!$N:$N,'2023-03'!$E:$E,Trésorerie!T$4,'2023-03'!$F:$F,Trésorerie!$B19) -> 0 | U19: =-SUMIFS('2023-04'!$M:$M,'2023-04'!$E:$E,Trésorerie!U$4,'2023-04'!$F:$F,Trésorerie!$B19)+SUMIFS('2023-04'!$N:$N,'2023-04'!$E:$E,Trésorerie!U$4,'2023-04'!$F:$F,Trésorerie!$B19) -> 0 | V19: =-SUMIFS('2023-05'!$M:$M,'2023-05'!$E:$E,Trésorerie!V$4,'2023-05'!$F:$F,Trésorerie!$B19)+SUMIFS('2023-05'!$N:$N,'2023-05'!$E:$E,Trésorerie!V$4,'2023-05'!$F:$F,Trésorerie!$B19) -> 0 | W19: =-SUMIFS('2023-06'!$M:$M,'2023-06'!$E:$E,Trésorerie!W$4,'2023-06'!$F:$F,Trésorerie!$B19)+SUMIFS('2023-06'!$N:$N,'2023-06'!$E:$E,Trésorerie!W$4,'2023-06'!$F:$F,Trésorerie!$B19) -> 0 | X19: =-SUMIFS('2023-07'!$M:$M,'2023-07'!$E:$E,Trésorerie!X$4,'2023-07'!$F:$F,Trésorerie!$B19)+SUMIFS('2023-07'!$N:$N,'2023-07'!$E:$E,Trésorerie!X$4,'2023-07'!$F:$F,Trésorerie!$B19) -> 0 | Y19: =-SUMIFS('2023-08'!$M:$M,'2023-08'!$E:$E,Trésorerie!Y$4,'2023-08'!$F:$F,Trésorerie!$B19)+SUMIFS('2023-08'!$N:$N,'2023-08'!$E:$E,Trésorerie!Y$4,'2023-08'!$F:$F,Trésorerie!$B19) -> 0 | Z19: =-SUMIFS('2023-09'!$M:$M,'2023-09'!$E:$E,Trésorerie!Z$4,'2023-09'!$F:$F,Trésorerie!$B19)+SUMIFS('2023-09'!$N:$N,'2023-09'!$E:$E,Trésorerie!Z$4,'2023-09'!$F:$F,Trésorerie!$B19) -> 17163.72 | AA19: =-SUMIFS('2023-10'!$M:$M,'2023-10'!$E:$E,Trésorerie!AA$4,'2023-10'!$F:$F,Trésorerie!$B19)+SUMIFS('2023-10'!$N:$N,'2023-10'!$E:$E,Trésorerie!AA$4,'2023-10'!$F:$F,Trésorerie!$B19) -> 0 | AB19: =IF(SUM($E19:O19)>SUM($R19:AA19),SUM($E19:O19)-SUM($R19:AA19),0) -> 0 | AC19: =IF(SUM($E19:P19)>SUM($R19:AB19),SUM($E19:P19)-SUM($R19:AB19),0) -> 0
A20: =SUM(E20:P20) -> 16596.45 | B20: 791100 | C20: TRANSFERT CHARGES UNIFORMATION | D20: Entrée | E20: =-SUMIFS('2022'!$M:$M,'2022'!$E:$E,Trésorerie!E$4,'2022'!$F:$F,Trésorerie!$B20)+SUMIFS('2022'!$N:$N,'2022'!$E:$E,Trésorerie!E$4,'2022'!$F:$F,Trésorerie!$B20) -> 0 | F20: =-SUMIFS('2022'!$M:$M,'2022'!$E:$E,Trésorerie!F$4,'2022'!$F:$F,Trésorerie!$B20)+SUMIFS('2022'!$N:$N,'2022'!$E:$E,Trésorerie!F$4,'2022'!$F:$F,Trésorerie!$B20) -> 0 | G20: =-SUMIFS('2022'!$M:$M,'2022'!$E:$E,Trésorerie!G$4,'2022'!$F:$F,Trésorerie!$B20)+SUMIFS('2022'!$N:$N,'2022'!$E:$E,Trésorerie!G$4,'2022'!$F:$F,Trésorerie!$B20) -> 3384 | H20: =-SUMIFS('2022'!$M:$M,'2022'!$E:$E,Trésorerie!H$4,'2022'!$F:$F,Trésorerie!$B20)+SUMIFS('2022'!$N:$N,'2022'!$E:$E,Trésorerie!H$4,'2022'!$F:$F,Trésorerie!$B20) -> 0 | I20: =-SUMIFS('2022'!$M:$M,'2022'!$E:$E,Trésorerie!I$4,'2022'!$F:$F,Trésorerie!$B20)+SUMIFS('2022'!$N:$N,'2022'!$E:$E,Trésorerie!I$4,'2022'!$F:$F,Trésorerie!$B20) -> 345 | J20: =-SUMIFS('2022'!$M:$M,'2022'!$E:$E,Trésorerie!J$4,'2022'!$F:$F,Trésorerie!$B20)+SUMIFS('2022'!$N:$N,'2022'!$E:$E,Trésorerie!J$4,'2022'!$F:$F,Trésorerie!$B20) -> 2399.45 | K20: =-SUMIFS('2022'!$M:$M,'2022'!$E:$E,Trésorerie!K$4,'2022'!$F:$F,Trésorerie!$B20)+SUMIFS('2022'!$N:$N,'2022'!$E:$E,Trésorerie!K$4,'2022'!$F:$F,Trésorerie!$B20) -> 1960 | L20: =-SUMIFS('2022'!$M:$M,'2022'!$E:$E,Trésorerie!L$4,'2022'!$F:$F,Trésorerie!$B20)+SUMIFS('2022'!$N:$N,'2022'!$E:$E,Trésorerie!L$4,'2022'!$F:$F,Trésorerie!$B20) -> 438 | ... P20: =-SUMIFS('2022'!$M:$M,'2022'!$E:$E,Trésorerie!P$4,'2022'!$F:$F,Trésorerie!$B20)+SUMIFS('2022'!$N:$N,'2022'!$E:$E,Trésorerie!P$4,'2022'!$F:$F,Trésorerie!$B20) -> 0 | R20: =-SUMIFS('2023-01'!$M:$M,'2023-01'!$E:$E,Trésorerie!R$4,'2023-01'!$F:$F,Trésorerie!$B20)+SUMIFS('2023-01'!$N:$N,'2023-01'!$E:$E,Trésorerie!R$4,'2023-01'!$F:$F,Trésorerie!$B20) -> 5076 | S20: =-SUMIFS('2023-02'!$M:$M,'2023-02'!$E:$E,Trésorerie!S$4,'2023-02'!$F:$F,Trésorerie!$B20)+SUMIFS('2023-02'!$N:$N,'2023-02'!$E:$E,Trésorerie!S$4,'2023-02'!$F:$F,Trésorerie!$B20) -> 0 | T20: =-SUMIFS('2023-03'!$M:$M,'2023-03'!$E:$E,Trésorerie!T$4,'2023-03'!$F:$F,Trésorerie!$B20)+SUMIFS('2023-03'!$N:$N,'2023-03'!$E:$E,Trésorerie!T$4,'2023-03'!$F:$F,Trésorerie!$B20) -> 4663 | U20: =-SUMIFS('2023-04'!$M:$M,'2023-04'!$E:$E,Trésorerie!U$4,'2023-04'!$F:$F,Trésorerie!$B20)+SUMIFS('2023-04'!$N:$N,'2023-04'!$E:$E,Trésorerie!U$4,'2023-04'!$F:$F,Trésorerie!$B20) -> 0 | V20: =-SUMIFS('2023-05'!$M:$M,'2023-05'!$E:$E,Trésorerie!V$4,'2023-05'!$F:$F,Trésorerie!$B20)+SUMIFS('2023-05'!$N:$N,'2023-05'!$E:$E,Trésorerie!V$4,'2023-05'!$F:$F,Trésorerie!$B20) -> 0 | W20: =-SUMIFS('2023-06'!$M:$M,'2023-06'!$E:$E,Trésorerie!W$4,'2023-06'!$F:$F,Trésorerie!$B20)+SUMIFS('2023-06'!$N:$N,'2023-06'!$E:$E,Trésorerie!W$4,'2023-06'!$F:$F,Trésorerie!$B20) -> 390 | X20: =-SUMIFS('2023-07'!$M:$M,'2023-07'!$E:$E,Trésorerie!X$4,'2023-07'!$F:$F,Trésorerie!$B20)+SUMIFS('2023-07'!$N:$N,'2023-07'!$E:$E,Trésorerie!X$4,'2023-07'!$F:$F,Trésorerie!$B20) -> 0 | Y20: =-SUMIFS('2023-08'!$M:$M,'2023-08'!$E:$E,Trésorerie!Y$4,'2023-08'!$F:$F,Trésorerie!$B20)+SUMIFS('2023-08'!$N:$N,'2023-08'!$E:$E,Trésorerie!Y$4,'2023-08'!$F:$F,Trésorerie!$B20) -> 0 | Z20: =-SUMIFS('2023-09'!$M:$M,'2023-09'!$E:$E,Trésorerie!Z$4,'2023-09'!$F:$F,Trésorerie!$B20)+SUMIFS('2023-09'!$N:$N,'2023-09'!$E:$E,Trésorerie!Z$4,'2023-09'!$F:$F,Trésorerie!$B20) -> 0 | AA20: =-SUMIFS('2023-10'!$M:$M,'2023-10'!$E:$E,Trésorerie!AA$4,'2023-10'!$F:$F,Trésorerie!$B20)+SUMIFS('2023-10'!$N:$N,'2023-10'!$E:$E,Trésorerie!AA$4,'2023-10'!$F:$F,Trésorerie!$B20) -> 0 | AB20: =IF(SUM($E20:O20)>SUM($R20:AA20),SUM($E20:O20)-SUM($R20:AA20),0) -> 6467.45 | AC20: =IF(SUM($E20:P20)>SUM($R20:AB20),SUM($E20:P20)-SUM($R20:AB20),0) -> 0
A21: =SUM(E21:P21) -> 9487.7 | B21: 411010 | C21: COLLECTIF CLIENTS BABILHOME | D21: Entrée | E21: =-SUMIFS('2022'!$M:$M,'2022'!$E:$E,Trésorerie!E$4,'2022'!$F:$F,Trésorerie!$B21)+SUMIFS('2022'!$N:$N,'2022'!$E:$E,Trésorerie!E$4,'2022'!$F:$F,Trésorerie!$B21) -> 537.28 | F21: =-SUMIFS('2022'!$M:$M,'2022'!$E:$E,Trésorerie!F$4,'2022'!$F:$F,Trésorerie!$B21)+SUMIFS('2022'!$N:$N,'2022'!$E:$E,Trésorerie!F$4,'2022'!$F:$F,Trésorerie!$B21) -> 854.38 | G21: =-SUMIFS('2022'!$M:$M,'2022'!$E:$E,Trésorerie!G$4,'2022'!$F:$F,Trésorerie!$B21)+SUMIFS('2022'!$N:$N,'2022'!$E:$E,Trésorerie!G$4,'2022'!$F:$F,Trésorerie!$B21) -> 765.8 | H21: =-SUMIFS('2022'!$M:$M,'2022'!$E:$E,Trésorerie!H$4,'2022'!$F:$F,Trésorerie!$B21)+SUMIFS('2022'!$N:$N,'2022'!$E:$E,Trésorerie!H$4,'2022'!$F:$F,Trésorerie!$B21) -> 1085.43 | I21: =-SUMIFS('2022'!$M:$M,'2022'!$E:$E,Trésorerie!I$4,'2022'!$F:$F,Trésorerie!$B21)+SUMIFS('2022'!$N:$N,'2022'!$E:$E,Trésorerie!I$4,'2022'!$F:$F,Trésorerie!$B21) -> 933.93 | J21: =-SUMIFS('2022'!$M:$M,'2022'!$E:$E,Trésorerie!J$4,'2022'!$F:$F,Trésorerie!$B21)+SUMIFS('2022'!$N:$N,'2022'!$E:$E,Trésorerie!J$4,'2022'!$F:$F,Trésorerie!$B21) -> 808.06 | K21: =-SUMIFS('2022'!$M:$M,'2022'!$E:$E,Trésorerie!K$4,'2022'!$F:$F,Trésorerie!$B21)+SUMIFS('2022'!$N:$N,'2022'!$E:$E,Trésorerie!K$4,'2022'!$F:$F,Trésorerie!$B21) -> 556.99 | L21: =-SUMIFS('2022'!$M:$M,'2022'!$E:$E,Trésorerie!L$4,'2022'!$F:$F,Trésorerie!$B21)+SUMIFS('2022'!$N:$N,'2022'!$E:$E,Trésorerie!L$4,'2022'!$F:$F,Trésorerie!$B21) -> 362 | ... P21: =-SUMIFS('2022'!$M:$M,'2022'!$E:$E,Trésorerie!P$4,'2022'!$F:$F,Trésorerie!$B21)+SUMIFS('2022'!$N:$N,'2022'!$E:$E,Trésorerie!P$4,'2022'!$F:$F,Trésorerie!$B21) -> 1392.31 | R21: =-SUMIFS('2023-01'!$M:$M,'2023-01'!$E:$E,Trésorerie!R$4,'2023-01'!$F:$F,Trésorerie!$B21)+SUMIFS('2023-01'!$N:$N,'2023-01'!$E:$E,Trésorerie!R$4,'2023-01'!$F:$F,Trésorerie!$B21) -> 1509.75 | S21: =-SUMIFS('2023-02'!$M:$M,'2023-02'!$E:$E,Trésorerie!S$4,'2023-02'!$F:$F,Trésorerie!$B21)+SUMIFS('2023-02'!$N:$N,'2023-02'!$E:$E,Trésorerie!S$4,'2023-02'!$F:$F,Trésorerie!$B21) -> 1269.76 | T21: =-SUMIFS('2023-03'!$M:$M,'2023-03'!$E:$E,Trésorerie!T$4,'2023-03'!$F:$F,Trésorerie!$B21)+SUMIFS('2023-03'!$N:$N,'2023-03'!$E:$E,Trésorerie!T$4,'2023-03'!$F:$F,Trésorerie!$B21) -> 842.76 | U21: =-SUMIFS('2023-04'!$M:$M,'2023-04'!$E:$E,Trésorerie!U$4,'2023-04'!$F:$F,Trésorerie!$B21)+SUMIFS('2023-04'!$N:$N,'2023-04'!$E:$E,Trésorerie!U$4,'2023-04'!$F:$F,Trésorerie!$B21) -> 2264.86 | V21: =-SUMIFS('2023-05'!$M:$M,'2023-05'!$E:$E,Trésorerie!V$4,'2023-05'!$F:$F,Trésorerie!$B21)+SUMIFS('2023-05'!$N:$N,'2023-05'!$E:$E,Trésorerie!V$4,'2023-05'!$F:$F,Trésorerie!$B21) -> 928.22 | W21: =-SUMIFS('2023-06'!$M:$M,'2023-06'!$E:$E,Trésorerie!W$4,'2023-06'!$F:$F,Trésorerie!$B21)+SUMIFS('2023-06'!$N:$N,'2023-06'!$E:$E,Trésorerie!W$4,'2023-06'!$F:$F,Trésorerie!$B21) -> 4158.73 | X21: =-SUMIFS('2023-07'!$M:$M,'2023-07'!$E:$E,Trésorerie!X$4,'2023-07'!$F:$F,Trésorerie!$B21)+SUMIFS('2023-07'!$N:$N,'2023-07'!$E:$E,Trésorerie!X$4,'2023-07'!$F:$F,Trésorerie!$B21) -> 1833.4 | Y21: =-SUMIFS('2023-08'!$M:$M,'2023-08'!$E:$E,Trésorerie!Y$4,'2023-08'!$F:$F,Trésorerie!$B21)+SUMIFS('2023-08'!$N:$N,'2023-08'!$E:$E,Trésorerie!Y$4,'2023-08'!$F:$F,Trésorerie!$B21) -> 1572.49 | Z21: =-SUMIFS('2023-09'!$M:$M,'2023-09'!$E:$E,Trésorerie!Z$4,'2023-09'!$F:$F,Trésorerie!$B21)+SUMIFS('2023-09'!$N:$N,'2023-09'!$E:$E,Trésorerie!Z$4,'2023-09'!$F:$F,Trésorerie!$B21) -> 815.68 | AA21: =-SUMIFS('2023-10'!$M:$M,'2023-10'!$E:$E,Trésorerie!AA$4,'2023-10'!$F:$F,Trésorerie!$B21)+SUMIFS('2023-10'!$N:$N,'2023-10'!$E:$E,Trésorerie!AA$4,'2023-10'!$F:$F,Trésorerie!$B21) -> 2167.14 | AB21: =IF(SUM($E21:O21)>SUM($R21:AA21),SUM($E21:O21)-SUM($R21:AA21),0) -> 0 | AC21: =IF(SUM($E21:P21)>SUM($R21:AB21),SUM($E21:P21)-SUM($R21:AB21),0) -> 0
